Workbook

Sheet Instrucciones
B2: Cuadrante de Guardias — Servicio de Anestesiología y Reanimación
B3: Octubre 2026 (1 oct – 2 nov, 33 días)
B5: Cómo está organizado este libro
B6: 1. Calendario Octubre 2026 — vista mensual tipo Guardiscope. Cada día tiene 5 casillas (TX, UCQ, MAY, PEQ, PEQ). Rellena con el desplegable de cada casilla (respeta la elegibilidad de cada puesto).
B7: 2. Resumen de guardias (estilo Guardiscope) — tabla de sanitarios con rango objetivo por puesto y recuento real, calculado en vivo desde el Calendario.
B8: 3. Validación H-01 a H-18 — checklist de reglas duras y puntuación de reglas blandas S-01 a S-07. Lo rellena el agente revisor-optimizador tras cada pasada.
B9: 4. Preguntas pendientes (Q) — decisiones sin cerrar en la fuente de la verdad (Q-04 a Q-16). Resuélvelas aquí; el agente las usará como supuestos confirmados.
B10: 5. Plantilla y elegibilidad — los 25 residentes con su ID único y los puestos que pueden cubrir.
B11: 6. Bloqueos y vacaciones — vacaciones/bloqueos declarados y el parte de guardias externas de Ana R4.
B12: 7. Reglas (resumen) — versión condensada de las reglas duras H y blandas S para consulta rápida sin salir del Excel.
B14: Leyenda de prefijos de las casillas
B15: TX = Localizada de trasplante (solo R4) · UCQ = REA/UCQ · MAY = Quirófano residente mayor (QX-M) · PEQ = Quirófano residente pequeño (QX-P, 2 plazas/día)
... B25: Este Excel es una herramienta de trabajo, no la fuente de la verdad. Las reglas completas (H-01 a H-18, S-01 a S-07) viven en fuente-verdad-guardias-anestesia.md, en el repositorio, y el agente de Claude Code 'guardias-anestesia' las aplica al ayudarte a rellenar y validar este cuadrante. Ante conflicto entre este Excel y ese documento, manda el documento.

Sheet Calendario Octubre 2026
A1: CUADRANTE DE GUARDIAS · Anestesiología y Reanimación · Octubre 2026 (1 oct – 2 nov)
A2: TX | B2: Trasplante (R4) | D2: UCQ | E2: REA / UCQ | G2: MAY | H2: Quirófano mayor | J2: PEQ | K2: Quirófano pequeño ×2 | M2: verde = fijado
A4: LUN | C4: MAR | E4: MIÉ | G4: JUE | I4: VIE | K4: SÁB | M4: DOM
G5: 1 | I5: 2 | K5: 3 | M5: 4
G7: TX | H7: TX-Isa | I7: TX | J7: TX-Sandra | K7: TX | L7: TX-Sandra | M7: TX | N7: TX-Sandra
G8: UCQ | H8: UCQ-PatriciaR2 | I8: UCQ | J8: UCQ-Fabian | K8: UCQ | L8: UCQ-PatriciaR2 | M8: UCQ | N8: UCQ-Fabian
G9: MAY | H9: MAY-Almudena | I9: MAY | J9: MAY-Candela | K9: MAY | L9: MAY-PatriciaR3 | M9: MAY | N9: MAY-Candela
G10: PEQ | H10: PEQ-Mercedes | I10: PEQ | J10: PEQ-Arturo | K10: PEQ | L10: PEQ-Miriam | M10: PEQ | N10: PEQ-Arturo
G11: PEQ | H11: PEQ-Fatima | I11: PEQ | J11: PEQ-Marc | K11: PEQ | L11: PEQ-David | M11: PEQ | N11: PEQ-Marc
G12: ⛔ AnaR4, Emi, Eva | I12: ⛔ Aitor, Almu, Carlota, Cris, Eva, Merce, Rosa | K12: ⛔ Aitor, Almu, AnaR2, Carlota, Cris, Eva, Merce, Rosa | M12: ⛔ Aitor, Almu, AnaR2, AnaR4, Carlota, Cris, Eva, Isa, Merce, Rosa
A14: 5 | C14: 6 | E14: 7 | G14: 8 | I14: 9 | K14: 10 | M14: 11
A16: TX | B16: TX-AnaR4 | C16: TX | D16: TX-Sandra | E16: TX | F16: TX-Almudena | G16: TX | H16: TX-Carlota | I16: TX | J16: TX-Isa | K16: TX | L16: TX-Isa | M16: TX | N16: TX-Isa
A17: UCQ | B17: UCQ-AnaR2 | C17: UCQ | D17: UCQ-PatriciaR2 | E17: UCQ | F17: UCQ-Tony | G17: UCQ | H17: UCQ-Fabian | I17: UCQ | J17: UCQ-Tania | K17: UCQ | L17: UCQ-AnaR2 | M17: UCQ | N17: UCQ-Tania
A18: MAY | B18: MAY-Isa | C18: MAY | D18: MAY-Candela | E18: MAY | F18: MAY-Isa | G18: MAY | H18: MAY-Sandra | I18: MAY | K18: MAY | L18: MAY-Sandra | M18: MAY
A19: PEQ | B19: PEQ-Fatima | C19: PEQ | D19: PEQ-Miriam | E19: PEQ | F19: PEQ-Cristina | G19: PEQ | H19: PEQ-Arturo | I19: PEQ | J19: PEQ-Rosario | K19: PEQ | L19: PEQ-Mercedes | M19: PEQ | N19: PEQ-Rosario
A20: PEQ | B20: PEQ-Asis | C20: PEQ | D20: PEQ-Mercedes | E20: PEQ | F20: PEQ-David | G20: PEQ | H20: PEQ-Aitor | I20: PEQ | J20: PEQ-Antonio | K20: PEQ | L20: PEQ-Eva | M20: PEQ | N20: PEQ-Antonio
A21: ⛔ Eva | C21: ⛔ Eva | E21: ⛔ AnaR4, Eva | G21: ⛔ Asís, Cande, Eva, PatR3 | I21: ⛔ Almu, Asís, Cande, Fati, Miri, PatR3, Tony | K21: ⛔ Almu, AnaR4, Fati, Miri, PatR3, Tania, Tony | M21: ⛔ Almu, Carlota, Fati, Miri, PatR3, Tony
A23: ★ 12 | C23: 13 | E23: 14 | G23: 15 | I23: 16 | K23: 17 | M23: 18
A25: TX | B25: TX-Isa | C25: TX | D25: TX-Carlota | E25: TX | F25: TX-Carlota | G25: TX | H25: TX-Sandra | I25: TX | J25: TX-Carlota | K25: TX | L25: TX-Carlota | M25: TX | N25: TX-Carlota
A26: UCQ | B26: UCQ-AnaR2 | C26: UCQ | D26: UCQ-Tania | E26: UCQ | F26: UCQ-Tony | G26: UCQ | H26: UCQ-Marc | I26: UCQ | J26: UCQ-AnaR2 | K26: UCQ | L26: UCQ-Fabian | M26: UCQ | N26: UCQ-AnaR2
A27: MAY | B27: MAY-Sandra | C27: MAY | D27: MAY-Candela | E27: MAY | F27: MAY-Almudena | G27: MAY | H27: MAY-AnaR4 | I27: MAY | J27: MAY-PatriciaR3 | K27: MAY | L27: MAY-Candela | M27: MAY | N27: MAY-PatriciaR3
A28: PEQ | B28: PEQ-Mercedes | C28: PEQ | D28: PEQ-Arturo | E28: PEQ | F28: PEQ-Mercedes | G28: PEQ | H28: PEQ-Rosario | I28: PEQ | J28: PEQ-Aitor | K28: PEQ | L28: PEQ-Miriam | M28: PEQ | N28: PEQ-Aitor
A29: PEQ | B29: PEQ-Eva | C29: PEQ | D29: PEQ-Emilio | E29: PEQ | F29: PEQ-AnaR2 | G29: PEQ | H29: PEQ-Eva | I29: PEQ | J29: PEQ-Asis | K29: PEQ | L29: PEQ-David | M29: PEQ | N29: PEQ-Asis
A30: ⛔ PatR3 | C30: ⛔ AnaR4 | E30: ⛔ Isa | G30: ⛔ Almu, Anto, Isa | I30: ⛔ Almu, AnaR4, Anto, Isa | K30: ⛔ Almu, AnaR4, Anto, Isa | M30: ⛔ Almu, AnaR4, Anto, Isa
A32: 19 | C32: 20 | E32: 21 | G32: 22 | I32: 23 | K32: 24 | M32: 25
A34: TX | B34: TX-AnaR4 | C34: TX | D34: TX-Isa | E34: TX | F34: TX-Sandra | G34: TX | H34: TX-AnaR4 | I34: TX | J34: TX-Almudena | K34: TX | L34: TX-Almudena | M34: TX | N34: TX-Almudena
A35: UCQ | B35: UCQ-Emilio | C35: UCQ | D35: UCQ-Fabian | E35: UCQ | F35: UCQ-Eva | G35: UCQ | H35: UCQ-PatriciaR2 | I35: UCQ | J35: UCQ-Tony | K35: UCQ | L35: UCQ-Tania | M35: UCQ | N35: UCQ-Tony
A36: MAY | B36: MAY-Sandra | C36: MAY | D36: MAY-Carlota | E36: MAY | F36: MAY-PatriciaR3 | G36: MAY | H36: MAY-Carlota | I36: MAY | J36: MAY-Isa | K36: MAY | L36: MAY-Sandra | M36: MAY | N36: MAY-Isa
A37: PEQ | B37: PEQ-Rosario | C37: PEQ | D37: PEQ-David | E37: PEQ | F37: PEQ-Cristina | G37: PEQ | H37: PEQ-Miriam | I37: PEQ | J37: PEQ-Eva | K37: PEQ | L37: PEQ-Emilio | M37: PEQ | N37: PEQ-Eva
A38: PEQ | B38: PEQ-Fatima | C38: PEQ | D38: PEQ-Aitor | E38: PEQ | F38: PEQ-Antonio | G38: PEQ | H38: PEQ-Emilio | I38: PEQ | J38: PEQ-Marc | K38: PEQ | L38: PEQ-Antonio | M38: PEQ | N38: PEQ-Marc
A39: ⛔ Almu | C39: ⛔ Almu | E39: ⛔ Almu, AnaR4, Rosa | G39: ⛔ Cande, Rosa | I39: ⛔ Aitor, AnaR2, Artu, Asís, Cande, Carlota, Cris, David, Fati, Merce, Miri, Rosa | K39: ⛔ Aitor, AnaR2, Artu, Asís, Cande, Carlota, Cris, David, Fabi, Fati, Merce, Miri, Rosa | M39: ⛔ Aitor, AnaR2, AnaR4, Artu, Asís, Cande, Carlota, Cris, David, Fabi, Fati, Merce, Miri, Rosa
A41: 26 | C41: 27 | E41: 28 | G41: 29 | I41: 30 | K41: 31 | M41: ★ 1 nov
A43: TX | B43: TX-Almudena | C43: TX | D43: TX-Sandra | E43: TX | F43: TX-Carlota | G43: TX | H43: TX-Isa | I43: TX | J43: TX-AnaR4 | K43: TX | L43: TX-AnaR4 | M43: TX | N43: TX-AnaR4
A44: UCQ | B44: UCQ-Fabian | C44: UCQ | D44: UCQ-Tania | E44: UCQ | F44: UCQ-Asis | G44: UCQ | H44: UCQ-Tania | I44: UCQ | J44: UCQ-PatriciaR2 | K44: UCQ | L44: UCQ-Tony | M44: UCQ | N44: UCQ-PatriciaR2
A45: MAY | B45: MAY-Carlota | C45: MAY | D45: MAY-Isa | E45: MAY | F45: MAY-Almudena | G45: MAY | H45: MAY-PatriciaR3 | I45: MAY | J45: MAY-Carlota | K45: MAY | L45: MAY-Almudena | M45: MAY | N45: MAY-Carlota
A46: PEQ | B46: PEQ-Miriam | C46: PEQ | D46: PEQ-Arturo | E46: PEQ | F46: PEQ-Aitor | G46: PEQ | H46: PEQ-Cristina | I46: PEQ | J46: PEQ-Fatima | K46: PEQ | L46: PEQ-Cristina | M46: PEQ | N46: PEQ-Fatima
A47: PEQ | B47: PEQ-David | C47: PEQ | D47: PEQ-Antonio | E47: PEQ | F47: PEQ-Marc | G47: PEQ | H47: PEQ-Antonio | I47: PEQ | J47: PEQ-Asis | K47: PEQ | L47: PEQ-Emilio | M47: PEQ | N47: PEQ-Asis
A48: ⛔ Emi | C48: ✔ sin bloqueos | E48: ⛔ AnaR4 | G48: ⛔ Sandra | I48: ⛔ Emi, Sandra | K48: ⛔ Sandra | M48: ⛔ Sandra
A50: ★ 2 nov
A52: TX | B52: TX-AnaR4
...

Sheet Cobertura por día
A1: COBERTURA POR DÍA · puestos a cubrir, asignados y pendientes (1 oct – 2 nov 2026)
A3: TOTALES — puestos que hay que cubrir cada día
A4: Turnos/Guardias | B4: Total | C4: 01/10 | D4: 02/10 | E4: 03/10 | F4: 04/10 | G4: 05/10 | H4: 06/10 | I4: 07/10 | J4: 08/10 | K4: 09/10 | L4: 10/10 | M4: 11/10 | N4: 12/10 | O4: 13/10 | P4: 14/10 | Q4: 15/10 | R4: 16/10 | S4: 17/10 | T4: 18/10 | U4: 19/10 | V4: 20/10 | W4: 21/10 | X4: 22/10 | Y4: 23/10 | Z4: 24/10 | AA4: 25/10 | AB4: 26/10 | AC4: 27/10 | AD4: 28/10 | AE4: 29/10 | AF4: 30/10 | AG4: 31/10 | AH4: 01/11 | AI4: 02/11
A5: Tx | B5: =SUM(C5:AI5) -> 33 | C5: 1 | D5: 1 | E5: 1 | F5: 1 | G5: 1 | H5: 1 | I5: 1 | J5: 1 | K5: 1 | L5: 1 | M5: 1 | N5: 1 | O5: 1 | P5: 1 | Q5: 1 | R5: 1 | S5: 1 | T5: 1 | U5: 1 | V5: 1 | W5: 1 | X5: 1 | Y5: 1 | Z5: 1 | AA5: 1 | AB5: 1 | AC5: 1 | AD5: 1 | AE5: 1 | AF5: 1 | AG5: 1 | AH5: 1 | AI5: 1
A6: ucq | B6: =SUM(C6:AI6) -> 33 | C6: 1 | D6: 1 | E6: 1 | F6: 1 | G6: 1 | H6: 1 | I6: 1 | J6: 1 | K6: 1 | L6: 1 | M6: 1 | N6: 1 | O6: 1 | P6: 1 | Q6: 1 | R6: 1 | S6: 1 | T6: 1 | U6: 1 | V6: 1 | W6: 1 | X6: 1 | Y6: 1 | Z6: 1 | AA6: 1 | AB6: 1 | AC6: 1 | AD6: 1 | AE6: 1 | AF6: 1 | AG6: 1 | AH6: 1 | AI6: 1
A7: MAYORES | B7: =SUM(C7:AI7) -> 33 | C7: 1 | D7: 1 | E7: 1 | F7: 1 | G7: 1 | H7: 1 | I7: 1 | J7: 1 | K7: 1 | L7: 1 | M7: 1 | N7: 1 | O7: 1 | P7: 1 | Q7: 1 | R7: 1 | S7: 1 | T7: 1 | U7: 1 | V7: 1 | W7: 1 | X7: 1 | Y7: 1 | Z7: 1 | AA7: 1 | AB7: 1 | AC7: 1 | AD7: 1 | AE7: 1 | AF7: 1 | AG7: 1 | AH7: 1 | AI7: 1
A8: qx peq | B8: =SUM(C8:AI8) -> 66 | C8: 2 | D8: 2 | E8: 2 | F8: 2 | G8: 2 | H8: 2 | I8: 2 | J8: 2 | K8: 2 | L8: 2 | M8: 2 | N8: 2 | O8: 2 | P8: 2 | Q8: 2 | R8: 2 | S8: 2 | T8: 2 | U8: 2 | V8: 2 | W8: 2 | X8: 2 | Y8: 2 | Z8: 2 | AA8: 2 | AB8: 2 | AC8: 2 | AD8: 2 | AE8: 2 | AF8: 2 | AG8: 2 | AH8: 2 | AI8: 2
A9: Total | B9: =SUM(C9:AI9) -> 165 | C9: =SUM(C5:C8) -> 5 | D9: =SUM(D5:D8) -> 5 | E9: =SUM(E5:E8) -> 5 | F9: =SUM(F5:F8) -> 5 | G9: =SUM(G5:G8) -> 5 | H9: =SUM(H5:H8) -> 5 | I9: =SUM(I5:I8) -> 5 | J9: =SUM(J5:J8) -> 5 | ... AI9: =SUM(AI5:AI8) -> 5
A11: ASIGNADOS — rellenados en el Calendario
A12: Turnos/Guardias | B12: Total | C12: 01/10 | D12: 02/10 | E12: 03/10 | F12: 04/10 | G12: 05/10 | H12: 06/10 | I12: 07/10 | J12: 08/10 | K12: 09/10 | L12: 10/10 | M12: 11/10 | N12: 12/10 | O12: 13/10 | P12: 14/10 | Q12: 15/10 | R12: 16/10 | S12: 17/10 | T12: 18/10 | U12: 19/10 | V12: 20/10 | W12: 21/10 | X12: 22/10 | Y12: 23/10 | Z12: 24/10 | AA12: 25/10 | AB12: 26/10 | AC12: 27/10 | AD12: 28/10 | AE12: 29/10 | AF12: 30/10 | AG12: 31/10 | AH12: 01/11 | AI12: 02/11
A13: Tx | B13: =SUM(C13:AI13) -> 33 | C13: =IF('Calendario Octubre 2026'!$H$7<>"",1,0) -> 1 | D13: =IF('Calendario Octubre 2026'!$J$7<>"",1,0) -> 1 | E13: =IF('Calendario Octubre 2026'!$L$7<>"",1,0) -> 1 | F13: =IF('Calendario Octubre 2026'!$N$7<>"",1,0) -> 1 | G13: =IF('Calendario Octubre 2026'!$B$16<>"",1,0) -> 1 | H13: =IF('Calendario Octubre 2026'!$D$16<>"",1,0) -> 1 | I13: =IF('Calendario Octubre 2026'!$F$16<>"",1,0) -> 1 | J13: =IF('Calendario Octubre 2026'!$H$16<>"",1,0) -> 1 | K13: =IF('Calendario Octubre 2026'!$J$16<>"",1,0) -> 1 | L13: =IF('Calendario Octubre 2026'!$L$16<>"",1,0) -> 1 | M13: =IF('Calendario Octubre 2026'!$N$16<>"",1,0) -> 1 | N13: =IF('Calendario Octubre 2026'!$B$25<>"",1,0) -> 1 | O13: =IF('Calendario Octubre 2026'!$D$25<>"",1,0) -> 1 | P13: =IF('Calendario Octubre 2026'!$F$25<>"",1,0) -> 1 | Q13: =IF('Calendario Octubre 2026'!$H$25<>"",1,0) -> 1 | R13: =IF('Calendario Octubre 2026'!$J$25<>"",1,0) -> 1 | S13: =IF('Calendario Octubre 2026'!$L$25<>"",1,0) -> 1 | T13: =IF('Calendario Octubre 2026'!$N$25<>"",1,0) -> 1 | U13: =IF('Calendario Octubre 2026'!$B$34<>"",1,0) -> 1 | V13: =IF('Calendario Octubre 2026'!$D$34<>"",1,0) -> 1 | W13: =IF('Calendario Octubre 2026'!$F$34<>"",1,0) -> 1 | X13: =IF('Calendario Octubre 2026'!$H$34<>"",1,0) -> 1 | Y13: =IF('Calendario Octubre 2026'!$J$34<>"",1,0) -> 1 | Z13: =IF('Calendario Octubre 2026'!$L$34<>"",1,0) -> 1 | AA13: =IF('Calendario Octubre 2026'!$N$34<>"",1,0) -> 1 | AB13: =IF('Calendario Octubre 2026'!$B$43<>"",1,0) -> 1 | AC13: =IF('Calendario Octubre 2026'!$D$43<>"",1,0) -> 1 | AD13: =IF('Calendario Octubre 2026'!$F$43<>"",1,0) -> 1 | AE13: =IF('Calendario Octubre 2026'!$H$43<>"",1,0) -> 1 | AF13: =IF('Calendario Octubre 2026'!$J$43<>"",1,0) -> 1 | AG13: =IF('Calendario Octubre 2026'!$L$43<>"",1,0) -> 1 | AH13: =IF('Calendario Octubre 2026'!$N$43<>"",1,0) -> 1 | AI13: =IF('Calendario Octubre 2026'!$B$52<>"",1,0) -> 1
A14: ucq | B14: =SUM(C14:AI14) -> 33 | C14: =IF('Calendario Octubre 2026'!$H$8<>"",1,0) -> 1 | D14: =IF('Calendario Octubre 2026'!$J$8<>"",1,0) -> 1 | E14: =IF('Calendario Octubre 2026'!$L$8<>"",1,0) -> 1 | F14: =IF('Calendario Octubre 2026'!$N$8<>"",1,0) -> 1 | G14: =IF('Calendario Octubre 2026'!$B$17<>"",1,0) -> 1 | H14: =IF('Calendario Octubre 2026'!$D$17<>"",1,0) -> 1 | I14: =IF('Calendario Octubre 2026'!$F$17<>"",1,0) -> 1 | J14: =IF('Calendario Octubre 2026'!$H$17<>"",1,0) -> 1 | K14: =IF('Calendario Octubre 2026'!$J$17<>"",1,0) -> 1 | L14: =IF('Calendario Octubre 2026'!$L$17<>"",1,0) -> 1 | M14: =IF('Calendario Octubre 2026'!$N$17<>"",1,0) -> 1 | N14: =IF('Calendario Octubre 2026'!$B$26<>"",1,0) -> 1 | O14: =IF('Calendario Octubre 2026'!$D$26<>"",1,0) -> 1 | P14: =IF('Calendario Octubre 2026'!$F$26<>"",1,0) -> 1 | Q14: =IF('Calendario Octubre 2026'!$H$26<>"",1,0) -> 1 | R14: =IF('Calendario Octubre 2026'!$J$26<>"",1,0) -> 1 | S14: =IF('Calendario Octubre 2026'!$L$26<>"",1,0) -> 1 | T14: =IF('Calendario Octubre 2026'!$N$26<>"",1,0) -> 1 | U14: =IF('Calendario Octubre 2026'!$B$35<>"",1,0) -> 1 | V14: =IF('Calendario Octubre 2026'!$D$35<>"",1,0) -> 1 | W14: =IF('Calendario Octubre 2026'!$F$35<>"",1,0) -> 1 | X14: =IF('Calendario Octubre 2026'!$H$35<>"",1,0) -> 1 | Y14: =IF('Calendario Octubre 2026'!$J$35<>"",1,0) -> 1 | Z14: =IF('Calendario Octubre 2026'!$L$35<>"",1,0) -> 1 | AA14: =IF('Calendario Octubre 2026'!$N$35<>"",1,0) -> 1 | AB14: =IF('Calendario Octubre 2026'!$B$44<>"",1,0) -> 1 | AC14: =IF('Calendario Octubre 2026'!$D$44<>"",1,0) -> 1 | AD14: =IF('Calendario Octubre 2026'!$F$44<>"",1,0) -> 1 | AE14: =IF('Calendario Octubre 2026'!$H$44<>"",1,0) -> 1 | AF14: =IF('Calendario Octubre 2026'!$J$44<>"",1,0) -> 1 | AG14: =IF('Calendario Octubre 2026'!$L$44<>"",1,0) -> 1 | AH14: =IF('Calendario Octubre 2026'!$N$44<>"",1,0) -> 1 | AI14: =IF('Calendario Octubre 2026'!$B$53<>"",1,0) -> 1
A15: MAYORES | B15: =SUM(C15:AI15) -> 31 | C15: =IF('Calendario Octubre 2026'!$H$9<>"",1,0) -> 1 | D15: =IF('Calendario Octubre 2026'!$J$9<>"",1,0) -> 1 | E15: =IF('Calendario Octubre 2026'!$L$9<>"",1,0) -> 1 | F15: =IF('Calendario Octubre 2026'!$N$9<>"",1,0) -> 1 | G15: =IF('Calendario Octubre 2026'!$B$18<>"",1,0) -> 1 | H15: =IF('Calendario Octubre 2026'!$D$18<>"",1,0) -> 1 | I15: =IF('Calendario Octubre 2026'!$F$18<>"",1,0) -> 1 | J15: =IF('Calendario Octubre 2026'!$H$18<>"",1,0) -> 1 | K15: =IF('Calendario Octubre 2026'!$J$18<>"",1,0) -> 0 | L15: =IF('Calendario Octubre 2026'!$L$18<>"",1,0) -> 1 | M15: =IF('Calendario Octubre 2026'!$N$18<>"",1,0) -> 0 | N15: =IF('Calendario Octubre 2026'!$B$27<>"",1,0) -> 1 | O15: =IF('Calendario Octubre 2026'!$D$27<>"",1,0) -> 1 | P15: =IF('Calendario Octubre 2026'!$F$27<>"",1,0) -> 1 | Q15: =IF('Calendario Octubre 2026'!$H$27<>"",1,0) -> 1 | R15: =IF('Calendario Octubre 2026'!$J$27<>"",1,0) -> 1 | S15: =IF('Calendario Octubre 2026'!$L$27<>"",1,0) -> 1 | T15: =IF('Calendario Octubre 2026'!$N$27<>"",1,0) -> 1 | U15: =IF('Calendario Octubre 2026'!$B$36<>"",1,0) -> 1 | V15: =IF('Calendario Octubre 2026'!$D$36<>"",1,0) -> 1 | W15: =IF('Calendario Octubre 2026'!$F$36<>"",1,0) -> 1 | X15: =IF('Calendario Octubre 2026'!$H$36<>"",1,0) -> 1 | Y15: =IF('Calendario Octubre 2026'!$J$36<>"",1,0) -> 1 | Z15: =IF('Calendario Octubre 2026'!$L$36<>"",1,0) -> 1 | AA15: =IF('Calendario Octubre 2026'!$N$36<>"",1,0) -> 1 | AB15: =IF('Calendario Octubre 2026'!$B$45<>"",1,0) -> 1 | AC15: =IF('Calendario Octubre 2026'!$D$45<>"",1,0) -> 1 | AD15: =IF('Calendario Octubre 2026'!$F$45<>"",1,0) -> 1 | AE15: =IF('Calendario Octubre 2026'!$H$45<>"",1,0) -> 1 | AF15: =IF('Calendario Octubre 2026'!$J$45<>"",1,0) -> 1 | AG15: =IF('Calendario Octubre 2026'!$L$45<>"",1,0) -> 1 | AH15: =IF('Calendario Octubre 2026'!$N$45<>"",1,0) -> 1 | AI15: =IF('Calendario Octubre 2026'!$B$54<>"",1,0) -> 1
A16: qx peq | B16: =SUM(C16:AI16) -> 66 | C16: =IF('Calendario Octubre 2026'!$H$10<>"",1,0)+IF('Calendario Octubre 2026'!$H$11<>"",1,0) -> 2 | D16: =IF('Calendario Octubre 2026'!$J$10<>"",1,0)+IF('Calendario Octubre 2026'!$J$11<>"",1,0) -> 2 | E16: =IF('Calendario Octubre 2026'!$L$10<>"",1,0)+IF('Calendario Octubre 2026'!$L$11<>"",1,0) -> 2 | F16: =IF('Calendario Octubre 2026'!$N$10<>"",1,0)+IF('Calendario Octubre 2026'!$N$11<>"",1,0) -> 2 | G16: =IF('Calendario Octubre 2026'!$B$19<>"",1,0)+IF('Calendario Octubre 2026'!$B$20<>"",1,0) -> 2 | H16: =IF('Calendario Octubre 2026'!$D$19<>"",1,0)+IF('Calendario Octubre 2026'!$D$20<>"",1,0) -> 2 | I16: =IF('Calendario Octubre 2026'!$F$19<>"",1,0)+IF('Calendario Octubre 2026'!$F$20<>"",1,0) -> 2 | J16: =IF('Calendario Octubre 2026'!$H$19<>"",1,0)+IF('Calendario Octubre 2026'!$H$20<>"",1,0) -> 2 | K16: =IF('Calendario Octubre 2026'!$J$19<>"",1,0)+IF('Calendario Octubre 2026'!$J$20<>"",1,0) -> 2 | L16: =IF('Calendario Octubre 2026'!$L$19<>"",1,0)+IF('Calendario Octubre 2026'!$L$20<>"",1,0) -> 2 | M16: =IF('Calendario Octubre 2026'!$N$19<>"",1,0)+IF('Calendario Octubre 2026'!$N$20<>"",1,0) -> 2 | N16: =IF('Calendario Octubre 2026'!$B$28<>"",1,0)+IF('Calendario Octubre 2026'!$B$29<>"",1,0) -> 2 | O16: =IF('Calendario Octubre 2026'!$D$28<>"",1,0)+IF('Calendario Octubre 2026'!$D$29<>"",1,0) -> 2 | P16: =IF('Calendario Octubre 2026'!$F$28<>"",1,0)+IF('Calendario Octubre 2026'!$F$29<>"",1,0) -> 2 | Q16: =IF('Calendario Octubre 2026'!$H$28<>"",1,0)+IF('Calendario Octubre 2026'!$H$29<>"",1,0) -> 2 | R16: =IF('Calendario Octubre 2026'!$J$28<>"",1,0)+IF('Calendario Octubre 2026'!$J$29<>"",1,0) -> 2 | S16: =IF('Calendario Octubre 2026'!$L$28<>"",1,0)+IF('Calendario Octubre 2026'!$L$29<>"",1,0) -> 2 | T16: =IF('Calendario Octubre 2026'!$N$28<>"",1,0)+IF('Calendario Octubre 2026'!$N$29<>"",1,0) -> 2 | U16: =IF('Calendario Octubre 2026'!$B$37<>"",1,0)+IF('Calendario Octubre 2026'!$B$38<>"",1,0) -> 2 | V16: =IF('Calendario Octubre 2026'!$D$37<>"",1,0)+IF('Calendario Octubre 2026'!$D$38<>"",1,0) -> 2 | W16: =IF('Calendario Octubre 2026'!$F$37<>"",1,0)+IF('Calendario Octubre 2026'!$F$38<>"",1,0) -> 2 | X16: =IF('Calendario Octubre 2026'!$H$37<>"",1,0)+IF('Calendario Octubre 2026'!$H$38<>"",1,0) -> 2 | Y16: =IF('Calendario Octubre 2026'!$J$37<>"",1,0)+IF('Calendario Octubre 2026'!$J$38<>"",1,0) -> 2 | Z16: =IF('Calendario Octubre 2026'!$L$37<>"",1,0)+IF('Calendario Octubre 2026'!$L$38<>"",1,0) -> 2 | AA16: =IF('Calendario Octubre 2026'!$N$37<>"",1,0)+IF('Calendario Octubre 2026'!$N$38<>"",1,0) -> 2 | AB16: =IF('Calendario Octubre 2026'!$B$46<>"",1,0)+IF('Calendario Octubre 2026'!$B$47<>"",1,0) -> 2 | AC16: =IF('Calendario Octubre 2026'!$D$46<>"",1,0)+IF('Calendario Octubre 2026'!$D$47<>"",1,0) -> 2 | AD16: =IF('Calendario Octubre 2026'!$F$46<>"",1,0)+IF('Calendario Octubre 2026'!$F$47<>"",1,0) -> 2 | AE16: =IF('Calendario Octubre 2026'!$H$46<>"",1,0)+IF('Calendario Octubre 2026'!$H$47<>"",1,0) -> 2 | AF16: =IF('Calendario Octubre 2026'!$J$46<>"",1,0)+IF('Calendario Octubre 2026'!$J$47<>"",1,0) -> 2 | AG16: =IF('Calendario Octubre 2026'!$L$46<>"",1,0)+IF('Calendario Octubre 2026'!$L$47<>"",1,0) -> 2 | AH16: =IF('Calendario Octubre 2026'!$N$46<>"",1,0)+IF('Calendario Octubre 2026'!$N$47<>"",1,0) -> 2 | AI16: =IF('Calendario Octubre 2026'!$B$55<>"",1,0)+IF('Calendario Octubre 2026'!$B$56<>"",1,0) -> 2
A17: Total | B17: =SUM(C17:AI17) -> 163 | C17: =SUM(C13:C16) -> 5 | D17: =SUM(D13:D16) -> 5 | E17: =SUM(E13:E16) -> 5 | F17: =SUM(F13:F16) -> 5 | G17: =SUM(G13:G16) -> 5 | H17: =SUM(H13:H16) -> 5 | I17: =SUM(I13:I16) -> 5 | J17: =SUM(J13:J16) -> 5 | ... AI17: =SUM(AI13:AI16) -> 5
A19: PENDIENTES — lo que falta por cubrir
A20: Turnos/Guardias | B20: Total | C20: 01/10 | D20: 02/10 | E20: 03/10 | F20: 04/10 | G20: 05/10 | H20: 06/10 | I20: 07/10 | J20: 08/10 | K20: 09/10 | L20: 10/10 | M20: 11/10 | N20: 12/10 | O20: 13/10 | P20: 14/10 | Q20: 15/10 | R20: 16/10 | S20: 17/10 | T20: 18/10 | U20: 19/10 | V20: 20/10 | W20: 21/10 | X20: 22/10 | Y20: 23/10 | Z20: 24/10 | AA20: 25/10 | AB20: 26/10 | AC20: 27/10 | AD20: 28/10 | AE20: 29/10 | AF20: 30/10 | AG20: 31/10 | AH20: 01/11 | AI20: 02/11
A21: Tx | B21: =SUM(C21:AI21) -> 0 | C21: =C5-C13 -> 0 | D21: =D5-D13 -> 0 | E21: =E5-E13 -> 0 | F21: =F5-F13 -> 0 | G21: =G5-G13 -> 0 | H21: =H5-H13 -> 0 | I21: =I5-I13 -> 0 | J21: =J5-J13 -> 0 | ... AI21: =AI5-AI13 -> 0
A22: ucq | B22: =SUM(C22:AI22) -> 0 | C22: =C6-C14 -> 0 | D22: =D6-D14 -> 0 | E22: =E6-E14 -> 0 | F22: =F6-F14 -> 0 | G22: =G6-G14 -> 0 | H22: =H6-H14 -> 0 | I22: =I6-I14 -> 0 | J22: =J6-J14 -> 0 | ... AI22: =AI6-AI14 -> 0
A23: MAYORES | B23: =SUM(C23:AI23) -> 2 | C23: =C7-C15 -> 0 | D23: =D7-D15 -> 0 | E23: =E7-E15 -> 0 | F23: =F7-F15 -> 0 | G23: =G7-G15 -> 0 | H23: =H7-H15 -> 0 | I23: =I7-I15 -> 0 | J23: =J7-J15 -> 0 | ... AI23: =AI7-AI15 -> 0
A24: qx peq | B24: =SUM(C24:AI24) -> 0 | C24: =C8-C16 -> 0 | D24: =D8-D16 -> 0 | E24: =E8-E16 -> 0 | F24: =F8-F16 -> 0 | G24: =G8-G16 -> 0 | H24: =H8-H16 -> 0 | I24: =I8-I16 -> 0 | J24: =J8-J16 -> 0 | ... AI24: =AI8-AI16 -> 0
A25: Total | B25: =SUM(C25:AI25) -> 2 | C25: =SUM(C21:C24) -> 0 | D25: =SUM(D21:D24) -> 0 | E25: =SUM(E21:E24) -> 0 | F25: =SUM(F21:F24) -> 0 | G25: =SUM(G21:G24) -> 0 | H25: =SUM(H21:H24) -> 0 | I25: =SUM(I21:I24) -> 0 | J25: =SUM(J21:J24) -> 0 | ... AI25: =SUM(AI21:AI24) -> 0
A27: TOTALES es fijo (H-01: 1 Tx + 1 ucq + 1 MAY + 2 peq = 5 puestos/día × 33 días = 165). ASIGNADOS y PENDIENTES se calculan solos desde la pestaña Calendario. Columnas moradas = fin de semana, rojas = festivo.

Sheet Resumen de guardias
A1: Rangos objetivo (editable, según fuente de la verdad) | H1: Recuento real (formulas -> Calendario) | M1: Por día de la semana / festivos (recuento real)
A2: Sanitarios/as | B2: ID | C2: Total (objetivo) | D2: MAY (objetivo) | E2: Tx (objetivo) | F2: ucq (objetivo) | G2: peq (objetivo) | H2: MAY | I2: Tx | J2: ucq | K2: peq | L2: Total | M2: L | N2: M | O2: X | P2: J | Q2: V | R2: S | S2: D | T2: F
A3: Rosario | B3: R1-01 | G3: 3-4 | H3: =COUNTIF('Calendario Octubre 2026'!$A$5:$N$58,"MAY-Rosario") -> 0 | I3: =COUNTIF('Calendario Octubre 2026'!$A$5:$N$58,"TX-Rosario") -> 0 | J3: =COUNTIF('Calendario Octubre 2026'!$A$5:$N$58,"UCQ-Rosario") -> 0 | K3: =COUNTIF('Calendario Octubre 2026'!$A$5:$N$58,"PEQ-Rosario") -> 4 | L3: =SUM(H3:K3) -> 4 | M3: =COUNTIF('Calendario Octubre 2026'!$B$5:$B$58,"*-Rosario") -> 1 | N3: =COUNTIF('Calendario Octubre 2026'!$D$5:$D$58,"*-Rosario") -> 0 | O3: =COUNTIF('Calendario Octubre 2026'!$F$5:$F$58,"*-Rosario") -> 0 | P3: =COUNTIF('Calendario Octubre 2026'!$H$5:$H$58,"*-Rosario") -> 1 | Q3: =COUNTIF('Calendario Octubre 2026'!$J$5:$J$58,"*-Rosario") -> 1 | R3: =COUNTIF('Calendario Octubre 2026'!$L$5:$L$58,"*-Rosario") -> 0 | S3: =COUNTIF('Calendario Octubre 2026'!$N$5:$N$58,"*-Rosario") -> 1 | T3: =COUNTIF('Calendario Octubre 2026'!$B$25:$B$29,"*-Rosario")+COUNTIF('Calendario Octubre 2026'!$N$43:$N$47,"*-Rosario")+COUNTIF('Calendario Octubre 2026'!$B$52:$B$56,"*-Rosario") -> 0
A4: Cristina | B4: R1-02 | G4: 3-4 | H4: =COUNTIF('Calendario Octubre 2026'!$A$5:$N$58,"MAY-Cristina") -> 0 | I4: =COUNTIF('Calendario Octubre 2026'!$A$5:$N$58,"TX-Cristina") -> 0 | J4: =COUNTIF('Calendario Octubre 2026'!$A$5:$N$58,"UCQ-Cristina") -> 0 | K4: =COUNTIF('Calendario Octubre 2026'!$A$5:$N$58,"PEQ-Cristina") -> 5 | L4: =SUM(H4:K4) -> 5 | M4: =COUNTIF('Calendario Octubre 2026'!$B$5:$B$58,"*-Cristina") -> 1 | N4: =COUNTIF('Calendario Octubre 2026'!$D$5:$D$58,"*-Cristina") -> 0 | O4: =COUNTIF('Calendario Octubre 2026'!$F$5:$F$58,"*-Cristina") -> 2 | P4: =COUNTIF('Calendario Octubre 2026'!$H$5:$H$58,"*-Cristina") -> 1 | Q4: =COUNTIF('Calendario Octubre 2026'!$J$5:$J$58,"*-Cristina") -> 0 | R4: =COUNTIF('Calendario Octubre 2026'!$L$5:$L$58,"*-Cristina") -> 1 | S4: =COUNTIF('Calendario Octubre 2026'!$N$5:$N$58,"*-Cristina") -> 0 | T4: =COUNTIF('Calendario Octubre 2026'!$B$25:$B$29,"*-Cristina")+COUNTIF('Calendario Octubre 2026'!$N$43:$N$47,"*-Cristina")+COUNTIF('Calendario Octubre 2026'!$B$52:$B$56,"*-Cristina") -> 1
A5: Miriam | B5: R1-03 | G5: 4-5 | H5: =COUNTIF('Calendario Octubre 2026'!$A$5:$N$58,"MAY-Miriam") -> 0 | I5: =COUNTIF('Calendario Octubre 2026'!$A$5:$N$58,"TX-Miriam") -> 0 | J5: =COUNTIF('Calendario Octubre 2026'!$A$5:$N$58,"UCQ-Miriam") -> 0 | K5: =COUNTIF('Calendario Octubre 2026'!$A$5:$N$58,"PEQ-Miriam") -> 5 | L5: =SUM(H5:K5) -> 5 | M5: =COUNTIF('Calendario Octubre 2026'!$B$5:$B$58,"*-Miriam") -> 1 | N5: =COUNTIF('Calendario Octubre 2026'!$D$5:$D$58,"*-Miriam") -> 1 | O5: =COUNTIF('Calendario Octubre 2026'!$F$5:$F$58,"*-Miriam") -> 0 | P5: =COUNTIF('Calendario Octubre 2026'!$H$5:$H$58,"*-Miriam") -> 1 | Q5: =COUNTIF('Calendario Octubre 2026'!$J$5:$J$58,"*-Miriam") -> 0 | R5: =COUNTIF('Calendario Octubre 2026'!$L$5:$L$58,"*-Miriam") -> 2 | S5: =COUNTIF('Calendario Octubre 2026'!$N$5:$N$58,"*-Miriam") -> 0 | T5: =COUNTIF('Calendario Octubre 2026'!$B$25:$B$29,"*-Miriam")+COUNTIF('Calendario Octubre 2026'!$N$43:$N$47,"*-Miriam")+COUNTIF('Calendario Octubre 2026'!$B$52:$B$56,"*-Miriam") -> 0
A6: David | B6: R1-04 | G6: 3-4 | H6: =COUNTIF('Calendario Octubre 2026'!$A$5:$N$58,"MAY-David") -> 0 | I6: =COUNTIF('Calendario Octubre 2026'!$A$5:$N$58,"TX-David") -> 0 | J6: =COUNTIF('Calendario Octubre 2026'!$A$5:$N$58,"UCQ-David") -> 0 | K6: =COUNTIF('Calendario Octubre 2026'!$A$5:$N$58,"PEQ-David") -> 5 | L6: =SUM(H6:K6) -> 5 | M6: =COUNTIF('Calendario Octubre 2026'!$B$5:$B$58,"*-David") -> 1 | N6: =COUNTIF('Calendario Octubre 2026'!$D$5:$D$58,"*-David") -> 1 | O6: =COUNTIF('Calendario Octubre 2026'!$F$5:$F$58,"*-David") -> 1 | P6: =COUNTIF('Calendario Octubre 2026'!$H$5:$H$58,"*-David") -> 0 | Q6: =COUNTIF('Calendario Octubre 2026'!$J$5:$J$58,"*-David") -> 0 | R6: =COUNTIF('Calendario Octubre 2026'!$L$5:$L$58,"*-David") -> 2 | S6: =COUNTIF('Calendario Octubre 2026'!$N$5:$N$58,"*-David") -> 0 | T6: =COUNTIF('Calendario Octubre 2026'!$B$25:$B$29,"*-David")+COUNTIF('Calendario Octubre 2026'!$N$43:$N$47,"*-David")+COUNTIF('Calendario Octubre 2026'!$B$52:$B$56,"*-David") -> 0
A7: Mercedes | B7: R1-05 | G7: 3-4 | H7: =COUNTIF('Calendario Octubre 2026'!$A$5:$N$58,"MAY-Mercedes") -> 0 | I7: =COUNTIF('Calendario Octubre 2026'!$A$5:$N$58,"TX-Mercedes") -> 0 | J7: =COUNTIF('Calendario Octubre 2026'!$A$5:$N$58,"UCQ-Mercedes") -> 0 | K7: =COUNTIF('Calendario Octubre 2026'!$A$5:$N$58,"PEQ-Mercedes") -> 5 | L7: =SUM(H7:K7) -> 5 | M7: =COUNTIF('Calendario Octubre 2026'!$B$5:$B$58,"*-Mercedes") -> 1 | N7: =COUNTIF('Calendario Octubre 2026'!$D$5:$D$58,"*-Mercedes") -> 1 | O7: =COUNTIF('Calendario Octubre 2026'!$F$5:$F$58,"*-Mercedes") -> 1 | P7: =COUNTIF('Calendario Octubre 2026'!$H$5:$H$58,"*-Mercedes") -> 1 | Q7: =COUNTIF('Calendario Octubre 2026'!$J$5:$J$58,"*-Mercedes") -> 0 | R7: =COUNTIF('Calendario Octubre 2026'!$L$5:$L$58,"*-Mercedes") -> 1 | S7: =COUNTIF('Calendario Octubre 2026'!$N$5:$N$58,"*-Mercedes") -> 0 | T7: =COUNTIF('Calendario Octubre 2026'!$B$25:$B$29,"*-Mercedes")+COUNTIF('Calendario Octubre 2026'!$N$43:$N$47,"*-Mercedes")+COUNTIF('Calendario Octubre 2026'!$B$52:$B$56,"*-Mercedes") -> 1
A8: Arturo | B8: R1-06 | G8: 3-4 | H8: =COUNTIF('Calendario Octubre 2026'!$A$5:$N$58,"MAY-Arturo") -> 0 | I8: =COUNTIF('Calendario Octubre 2026'!$A$5:$N$58,"TX-Arturo") -> 0 | J8: =COUNTIF('Calendario Octubre 2026'!$A$5:$N$58,"UCQ-Arturo") -> 0 | K8: =COUNTIF('Calendario Octubre 2026'!$A$5:$N$58,"PEQ-Arturo") -> 5 | L8: =SUM(H8:K8) -> 5 | M8: =COUNTIF('Calendario Octubre 2026'!$B$5:$B$58,"*-Arturo") -> 0 | N8: =COUNTIF('Calendario Octubre 2026'!$D$5:$D$58,"*-Arturo") -> 2 | O8: =COUNTIF('Calendario Octubre 2026'!$F$5:$F$58,"*-Arturo") -> 0 | P8: =COUNTIF('Calendario Octubre 2026'!$H$5:$H$58,"*-Arturo") -> 1 | Q8: =COUNTIF('Calendario Octubre 2026'!$J$5:$J$58,"*-Arturo") -> 1 | R8: =COUNTIF('Calendario Octubre 2026'!$L$5:$L$58,"*-Arturo") -> 0 | S8: =COUNTIF('Calendario Octubre 2026'!$N$5:$N$58,"*-Arturo") -> 1 | T8: =COUNTIF('Calendario Octubre 2026'!$B$25:$B$29,"*-Arturo")+COUNTIF('Calendario Octubre 2026'!$N$43:$N$47,"*-Arturo")+COUNTIF('Calendario Octubre 2026'!$B$52:$B$56,"*-Arturo") -> 0
A9: Aitor | B9: R1-07 | G9: 3-4 | H9: =COUNTIF('Calendario Octubre 2026'!$A$5:$N$58,"MAY-Aitor") -> 0 | I9: =COUNTIF('Calendario Octubre 2026'!$A$5:$N$58,"TX-Aitor") -> 0 | J9: =COUNTIF('Calendario Octubre 2026'!$A$5:$N$58,"UCQ-Aitor") -> 0 | K9: =COUNTIF('Calendario Octubre 2026'!$A$5:$N$58,"PEQ-Aitor") -> 5 | L9: =SUM(H9:K9) -> 5 | M9: =COUNTIF('Calendario Octubre 2026'!$B$5:$B$58,"*-Aitor") -> 0 | N9: =COUNTIF('Calendario Octubre 2026'!$D$5:$D$58,"*-Aitor") -> 1 | O9: =COUNTIF('Calendario Octubre 2026'!$F$5:$F$58,"*-Aitor") -> 1 | P9: =COUNTIF('Calendario Octubre 2026'!$H$5:$H$58,"*-Aitor") -> 1 | Q9: =COUNTIF('Calendario Octubre 2026'!$J$5:$J$58,"*-Aitor") -> 1 | R9: =COUNTIF('Calendario Octubre 2026'!$L$5:$L$58,"*-Aitor") -> 0 | S9: =COUNTIF('Calendario Octubre 2026'!$N$5:$N$58,"*-Aitor") -> 1 | T9: =COUNTIF('Calendario Octubre 2026'!$B$25:$B$29,"*-Aitor")+COUNTIF('Calendario Octubre 2026'!$N$43:$N$47,"*-Aitor")+COUNTIF('Calendario Octubre 2026'!$B$52:$B$56,"*-Aitor") -> 0
A10: Fatima | B10: R1-08 | G10: 3-4 | H10: =COUNTIF('Calendario Octubre 2026'!$A$5:$N$58,"MAY-Fatima") -> 0 | I10: =COUNTIF('Calendario Octubre 2026'!$A$5:$N$58,"TX-Fatima") -> 0 | J10: =COUNTIF('Calendario Octubre 2026'!$A$5:$N$58,"UCQ-Fatima") -> 0 | K10: =COUNTIF('Calendario Octubre 2026'!$A$5:$N$58,"PEQ-Fatima") -> 5 | L10: =SUM(H10:K10) -> 5 | M10: =COUNTIF('Calendario Octubre 2026'!$B$5:$B$58,"*-Fatima") -> 2 | N10: =COUNTIF('Calendario Octubre 2026'!$D$5:$D$58,"*-Fatima") -> 0 | O10: =COUNTIF('Calendario Octubre 2026'!$F$5:$F$58,"*-Fatima") -> 0 | P10: =COUNTIF('Calendario Octubre 2026'!$H$5:$H$58,"*-Fatima") -> 1 | Q10: =COUNTIF('Calendario Octubre 2026'!$J$5:$J$58,"*-Fatima") -> 1 | R10: =COUNTIF('Calendario Octubre 2026'!$L$5:$L$58,"*-Fatima") -> 0 | S10: =COUNTIF('Calendario Octubre 2026'!$N$5:$N$58,"*-Fatima") -> 1 | T10: =COUNTIF('Calendario Octubre 2026'!$B$25:$B$29,"*-Fatima")+COUNTIF('Calendario Octubre 2026'!$N$43:$N$47,"*-Fatima")+COUNTIF('Calendario Octubre 2026'!$B$52:$B$56,"*-Fatima") -> 1
A11: Tania | B11: R2-01 | C11: 6 | F11: 6- | G11: 0 | H11: =COUNTIF('Calendario Octubre 2026'!$A$5:$N$58,"MAY-Tania") -> 0 | I11: =COUNTIF('Calendario Octubre 2026'!$A$5:$N$58,"TX-Tania") -> 0 | J11: =COUNTIF('Calendario Octubre 2026'!$A$5:$N$58,"UCQ-Tania") -> 6 | K11: =COUNTIF('Calendario Octubre 2026'!$A$5:$N$58,"PEQ-Tania") -> 0 | L11: =SUM(H11:K11) -> 6 | M11: =COUNTIF('Calendario Octubre 2026'!$B$5:$B$58,"*-Tania") -> 0 | N11: =COUNTIF('Calendario Octubre 2026'!$D$5:$D$58,"*-Tania") -> 2 | O11: =COUNTIF('Calendario Octubre 2026'!$F$5:$F$58,"*-Tania") -> 0 | P11: =COUNTIF('Calendario Octubre 2026'!$H$5:$H$58,"*-Tania") -> 1 | Q11: =COUNTIF('Calendario Octubre 2026'!$J$5:$J$58,"*-Tania") -> 1 | R11: =COUNTIF('Calendario Octubre 2026'!$L$5:$L$58,"*-Tania") -> 1 | S11: =COUNTIF('Calendario Octubre 2026'!$N$5:$N$58,"*-Tania") -> 1 | T11: =COUNTIF('Calendario Octubre 2026'!$B$25:$B$29,"*-Tania")+COUNTIF('Calendario Octubre 2026'!$N$43:$N$47,"*-Tania")+COUNTIF('Calendario Octubre 2026'!$B$52:$B$56,"*-Tania") -> 0
A12: Asis | B12: R2-02 | C12: 6 | F12: 1-2 | H12: =COUNTIF('Calendario Octubre 2026'!$A$5:$N$58,"MAY-Asis") -> 0 | I12: =COUNTIF('Calendario Octubre 2026'!$A$5:$N$58,"TX-Asis") -> 0 | J12: =COUNTIF('Calendario Octubre 2026'!$A$5:$N$58,"UCQ-Asis") -> 1 | K12: =COUNTIF('Calendario Octubre 2026'!$A$5:$N$58,"PEQ-Asis") -> 5 | L12: =SUM(H12:K12) -> 6 | M12: =COUNTIF('Calendario Octubre 2026'!$B$5:$B$58,"*-Asis") -> 1 | N12: =COUNTIF('Calendario Octubre 2026'!$D$5:$D$58,"*-Asis") -> 0 | O12: =COUNTIF('Calendario Octubre 2026'!$F$5:$F$58,"*-Asis") -> 1 | P12: =COUNTIF('Calendario Octubre 2026'!$H$5:$H$58,"*-Asis") -> 0 | Q12: =COUNTIF('Calendario Octubre 2026'!$J$5:$J$58,"*-Asis") -> 2 | R12: =COUNTIF('Calendario Octubre 2026'!$L$5:$L$58,"*-Asis") -> 0 | S12: =COUNTIF('Calendario Octubre 2026'!$N$5:$N$58,"*-Asis") -> 2 | T12: =COUNTIF('Calendario Octubre 2026'!$B$25:$B$29,"*-Asis")+COUNTIF('Calendario Octubre 2026'!$N$43:$N$47,"*-Asis")+COUNTIF('Calendario Octubre 2026'!$B$52:$B$56,"*-Asis") -> 1
A13: Patricia R2 | B13: R2-03 | C13: 6 | F13: 6- | G13: 0 | H13: =COUNTIF('Calendario Octubre 2026'!$A$5:$N$58,"MAY-PatriciaR2") -> 0 | I13: =COUNTIF('Calendario Octubre 2026'!$A$5:$N$58,"TX-PatriciaR2") -> 0 | J13: =COUNTIF('Calendario Octubre 2026'!$A$5:$N$58,"UCQ-PatriciaR2") -> 6 | K13: =COUNTIF('Calendario Octubre 2026'!$A$5:$N$58,"PEQ-PatriciaR2") -> 0 | L13: =SUM(H13:K13) -> 6 | M13: =COUNTIF('Calendario Octubre 2026'!$B$5:$B$58,"*-PatriciaR2") -> 0 | N13: =COUNTIF('Calendario Octubre 2026'!$D$5:$D$58,"*-PatriciaR2") -> 1 | O13: =COUNTIF('Calendario Octubre 2026'!$F$5:$F$58,"*-PatriciaR2") -> 0 | P13: =COUNTIF('Calendario Octubre 2026'!$H$5:$H$58,"*-PatriciaR2") -> 2 | Q13: =COUNTIF('Calendario Octubre 2026'!$J$5:$J$58,"*-PatriciaR2") -> 1 | R13: =COUNTIF('Calendario Octubre 2026'!$L$5:$L$58,"*-PatriciaR2") -> 1 | S13: =COUNTIF('Calendario Octubre 2026'!$N$5:$N$58,"*-PatriciaR2") -> 1 | T13: =COUNTIF('Calendario Octubre 2026'!$B$25:$B$29,"*-PatriciaR2")+COUNTIF('Calendario Octubre 2026'!$N$43:$N$47,"*-PatriciaR2")+COUNTIF('Calendario Octubre 2026'!$B$52:$B$56,"*-PatriciaR2") -> 1
A14: Eva | B14: R2-04 | C14: 6 | F14: 1-2 | H14: =COUNTIF('Calendario Octubre 2026'!$A$5:$N$58,"MAY-Eva") -> 0 | I14: =COUNTIF('Calendario Octubre 2026'!$A$5:$N$58,"TX-Eva") -> 0 | J14: =COUNTIF('Calendario Octubre 2026'!$A$5:$N$58,"UCQ-Eva") -> 1 | K14: =COUNTIF('Calendario Octubre 2026'!$A$5:$N$58,"PEQ-Eva") -> 5 | L14: =SUM(H14:K14) -> 6 | M14: =COUNTIF('Calendario Octubre 2026'!$B$5:$B$58,"*-Eva") -> 1 | N14: =COUNTIF('Calendario Octubre 2026'!$D$5:$D$58,"*-Eva") -> 0 | O14: =COUNTIF('Calendario Octubre 2026'!$F$5:$F$58,"*-Eva") -> 1 | P14: =COUNTIF('Calendario Octubre 2026'!$H$5:$H$58,"*-Eva") -> 1 | Q14: =COUNTIF('Calendario Octubre 2026'!$J$5:$J$58,"*-Eva") -> 1 | R14: =COUNTIF('Calendario Octubre 2026'!$L$5:$L$58,"*-Eva") -> 1 | S14: =COUNTIF('Calendario Octubre 2026'!$N$5:$N$58,"*-Eva") -> 1 | T14: =COUNTIF('Calendario Octubre 2026'!$B$25:$B$29,"*-Eva")+COUNTIF('Calendario Octubre 2026'!$N$43:$N$47,"*-Eva")+COUNTIF('Calendario Octubre 2026'!$B$52:$B$56,"*-Eva") -> 1
A15: Emilio | B15: R2-05 | C15: 6 | F15: 1-2 | H15: =COUNTIF('Calendario Octubre 2026'!$A$5:$N$58,"MAY-Emilio") -> 0 | I15: =COUNTIF('Calendario Octubre 2026'!$A$5:$N$58,"TX-Emilio") -> 0 | J15: =COUNTIF('Calendario Octubre 2026'!$A$5:$N$58,"UCQ-Emilio") -> 1 | K15: =COUNTIF('Calendario Octubre 2026'!$A$5:$N$58,"PEQ-Emilio") -> 5 | L15: =SUM(H15:K15) -> 6 | M15: =COUNTIF('Calendario Octubre 2026'!$B$5:$B$58,"*-Emilio") -> 2 | N15: =COUNTIF('Calendario Octubre 2026'!$D$5:$D$58,"*-Emilio") -> 1 | O15: =COUNTIF('Calendario Octubre 2026'!$F$5:$F$58,"*-Emilio") -> 0 | P15: =COUNTIF('Calendario Octubre 2026'!$H$5:$H$58,"*-Emilio") -> 1 | Q15: =COUNTIF('Calendario Octubre 2026'!$J$5:$J$58,"*-Emilio") -> 0 | R15: =COUNTIF('Calendario Octubre 2026'!$L$5:$L$58,"*-Emilio") -> 2 | S15: =COUNTIF('Calendario Octubre 2026'!$N$5:$N$58,"*-Emilio") -> 0 | T15: =COUNTIF('Calendario Octubre 2026'!$B$25:$B$29,"*-Emilio")+COUNTIF('Calendario Octubre 2026'!$N$43:$N$47,"*-Emilio")+COUNTIF('Calendario Octubre 2026'!$B$52:$B$56,"*-Emilio") -> 1
A16: Antonio | B16: R2-06 | C16: 6 | F16: 1-2 | H16: =COUNTIF('Calendario Octubre 2026'!$A$5:$N$58,"MAY-Antonio") -> 0 | I16: =COUNTIF('Calendario Octubre 2026'!$A$5:$N$58,"TX-Antonio") -> 0 | J16: =COUNTIF('Calendario Octubre 2026'!$A$5:$N$58,"UCQ-Antonio") -> 0 | K16: =COUNTIF('Calendario Octubre 2026'!$A$5:$N$58,"PEQ-Antonio") -> 6 | L16: =SUM(H16:K16) -> 6 | M16: =COUNTIF('Calendario Octubre 2026'!$B$5:$B$58,"*-Antonio") -> 0 | N16: =COUNTIF('Calendario Octubre 2026'!$D$5:$D$58,"*-Antonio") -> 1 | O16: =COUNTIF('Calendario Octubre 2026'!$F$5:$F$58,"*-Antonio") -> 1 | P16: =COUNTIF('Calendario Octubre 2026'!$H$5:$H$58,"*-Antonio") -> 1 | Q16: =COUNTIF('Calendario Octubre 2026'!$J$5:$J$58,"*-Antonio") -> 1 | R16: =COUNTIF('Calendario Octubre 2026'!$L$5:$L$58,"*-Antonio") -> 1 | S16: =COUNTIF('Calendario Octubre 2026'!$N$5:$N$58,"*-Antonio") -> 1 | T16: =COUNTIF('Calendario Octubre 2026'!$B$25:$B$29,"*-Antonio")+COUNTIF('Calendario Octubre 2026'!$N$43:$N$47,"*-Antonio")+COUNTIF('Calendario Octubre 2026'!$B$52:$B$56,"*-Antonio") -> 0
A17: Ana R2 | B17: R2-07 | C17: 6 | F17: 1-2 | H17: =COUNTIF('Calendario Octubre 2026'!$A$5:$N$58,"MAY-AnaR2") -> 0 | I17: =COUNTIF('Calendario Octubre 2026'!$A$5:$N$58,"TX-AnaR2") -> 0 | J17: =COUNTIF('Calendario Octubre 2026'!$A$5:$N$58,"UCQ-AnaR2") -> 5 | K17: =COUNTIF('Calendario Octubre 2026'!$A$5:$N$58,"PEQ-AnaR2") -> 1 | L17: =SUM(H17:K17) -> 6 | M17: =COUNTIF('Calendario Octubre 2026'!$B$5:$B$58,"*-AnaR2") -> 2 | N17: =COUNTIF('Calendario Octubre 2026'!$D$5:$D$58,"*-AnaR2") -> 0 | O17: =COUNTIF('Calendario Octubre 2026'!$F$5:$F$58,"*-AnaR2") -> 1 | P17: =COUNTIF('Calendario Octubre 2026'!$H$5:$H$58,"*-AnaR2") -> 0 | Q17: =COUNTIF('Calendario Octubre 2026'!$J$5:$J$58,"*-AnaR2") -> 1 | R17: =COUNTIF('Calendario Octubre 2026'!$L$5:$L$58,"*-AnaR2") -> 1 | S17: =COUNTIF('Calendario Octubre 2026'!$N$5:$N$58,"*-AnaR2") -> 1 | T17: =COUNTIF('Calendario Octubre 2026'!$B$25:$B$29,"*-AnaR2")+COUNTIF('Calendario Octubre 2026'!$N$43:$N$47,"*-AnaR2")+COUNTIF('Calendario Octubre 2026'!$B$52:$B$56,"*-AnaR2") -> 1
A18: Marc | B18: R2-08 | C18: 6 | F18: 1-2 | G18: 6 | H18: =COUNTIF('Calendario Octubre 2026'!$A$5:$N$58,"MAY-Marc") -> 0 | I18: =COUNTIF('Calendario Octubre 2026'!$A$5:$N$58,"TX-Marc") -> 0 | J18: =COUNTIF('Calendario Octubre 2026'!$A$5:$N$58,"UCQ-Marc") -> 1 | K18: =COUNTIF('Calendario Octubre 2026'!$A$5:$N$58,"PEQ-Marc") -> 5 | L18: =SUM(H18:K18) -> 6 | M18: =COUNTIF('Calendario Octubre 2026'!$B$5:$B$58,"*-Marc") -> 0 | N18: =COUNTIF('Calendario Octubre 2026'!$D$5:$D$58,"*-Marc") -> 0 | O18: =COUNTIF('Calendario Octubre 2026'!$F$5:$F$58,"*-Marc") -> 1 | P18: =COUNTIF('Calendario Octubre 2026'!$H$5:$H$58,"*-Marc") -> 1 | Q18: =COUNTIF('Calendario Octubre 2026'!$J$5:$J$58,"*-Marc") -> 2 | R18: =COUNTIF('Calendario Octubre 2026'!$L$5:$L$58,"*-Marc") -> 0 | S18: =COUNTIF('Calendario Octubre 2026'!$N$5:$N$58,"*-Marc") -> 2 | T18: =COUNTIF('Calendario Octubre 2026'!$B$25:$B$29,"*-Marc")+COUNTIF('Calendario Octubre 2026'!$N$43:$N$47,"*-Marc")+COUNTIF('Calendario Octubre 2026'!$B$52:$B$56,"*-Marc") -> 0
A19: Patricia R3 | B19: R3-01 | C19: 6 | D19: 6 | H19: =COUNTIF('Calendario Octubre 2026'!$A$5:$N$58,"MAY-PatriciaR3") -> 5 | I19: =COUNTIF('Calendario Octubre 2026'!$A$5:$N$58,"TX-PatriciaR3") -> 0 | J19: =COUNTIF('Calendario Octubre 2026'!$A$5:$N$58,"UCQ-PatriciaR3") -> 0 | K19: =COUNTIF('Calendario Octubre 2026'!$A$5:$N$58,"PEQ-PatriciaR3") -> 0 | L19: =SUM(H19:K19) -> 5 | M19: =COUNTIF('Calendario Octubre 2026'!$B$5:$B$58,"*-PatriciaR3") -> 0 | N19: =COUNTIF('Calendario Octubre 2026'!$D$5:$D$58,"*-PatriciaR3") -> 0 | O19: =COUNTIF('Calendario Octubre 2026'!$F$5:$F$58,"*-PatriciaR3") -> 1 | P19: =COUNTIF('Calendario Octubre 2026'!$H$5:$H$58,"*-PatriciaR3") -> 1 | Q19: =COUNTIF('Calendario Octubre 2026'!$J$5:$J$58,"*-PatriciaR3") -> 1 | R19: =COUNTIF('Calendario Octubre 2026'!$L$5:$L$58,"*-PatriciaR3") -> 1 | S19: =COUNTIF('Calendario Octubre 2026'!$N$5:$N$58,"*-PatriciaR3") -> 1 | T19: =COUNTIF('Calendario Octubre 2026'!$B$25:$B$29,"*-PatriciaR3")+COUNTIF('Calendario Octubre 2026'!$N$43:$N$47,"*-PatriciaR3")+COUNTIF('Calendario Octubre 2026'!$B$52:$B$56,"*-PatriciaR3") -> 0
A20: Candela | B20: R3-02 | C20: 6 | H20: =COUNTIF('Calendario Octubre 2026'!$A$5:$N$58,"MAY-Candela") -> 5 | I20: =COUNTIF('Calendario Octubre 2026'!$A$5:$N$58,"TX-Candela") -> 0 | J20: =COUNTIF('Calendario Octubre 2026'!$A$5:$N$58,"UCQ-Candela") -> 0 | K20: =COUNTIF('Calendario Octubre 2026'!$A$5:$N$58,"PEQ-Candela") -> 0 | L20: =SUM(H20:K20) -> 5 | M20: =COUNTIF('Calendario Octubre 2026'!$B$5:$B$58,"*-Candela") -> 0 | N20: =COUNTIF('Calendario Octubre 2026'!$D$5:$D$58,"*-Candela") -> 2 | O20: =COUNTIF('Calendario Octubre 2026'!$F$5:$F$58,"*-Candela") -> 0 | P20: =COUNTIF('Calendario Octubre 2026'!$H$5:$H$58,"*-Candela") -> 0 | Q20: =COUNTIF('Calendario Octubre 2026'!$J$5:$J$58,"*-Candela") -> 1 | R20: =COUNTIF('Calendario Octubre 2026'!$L$5:$L$58,"*-Candela") -> 1 | S20: =COUNTIF('Calendario Octubre 2026'!$N$5:$N$58,"*-Candela") -> 1 | T20: =COUNTIF('Calendario Octubre 2026'!$B$25:$B$29,"*-Candela")+COUNTIF('Calendario Octubre 2026'!$N$43:$N$47,"*-Candela")+COUNTIF('Calendario Octubre 2026'!$B$52:$B$56,"*-Candela") -> 0
A21: Fabian | B21: R3-03 | C21: 6 | F21: 6- | G21: 0 | H21: =COUNTIF('Calendario Octubre 2026'!$A$5:$N$58,"MAY-Fabian") -> 0 | I21: =COUNTIF('Calendario Octubre 2026'!$A$5:$N$58,"TX-Fabian") -> 0 | J21: =COUNTIF('Calendario Octubre 2026'!$A$5:$N$58,"UCQ-Fabian") -> 6 | K21: =COUNTIF('Calendario Octubre 2026'!$A$5:$N$58,"PEQ-Fabian") -> 0 | L21: =SUM(H21:K21) -> 6 | M21: =COUNTIF('Calendario Octubre 2026'!$B$5:$B$58,"*-Fabian") -> 1 | N21: =COUNTIF('Calendario Octubre 2026'!$D$5:$D$58,"*-Fabian") -> 1 | O21: =COUNTIF('Calendario Octubre 2026'!$F$5:$F$58,"*-Fabian") -> 0 | P21: =COUNTIF('Calendario Octubre 2026'!$H$5:$H$58,"*-Fabian") -> 1 | Q21: =COUNTIF('Calendario Octubre 2026'!$J$5:$J$58,"*-Fabian") -> 1 | R21: =COUNTIF('Calendario Octubre 2026'!$L$5:$L$58,"*-Fabian") -> 1 | S21: =COUNTIF('Calendario Octubre 2026'!$N$5:$N$58,"*-Fabian") -> 1 | T21: =COUNTIF('Calendario Octubre 2026'!$B$25:$B$29,"*-Fabian")+COUNTIF('Calendario Octubre 2026'!$N$43:$N$47,"*-Fabian")+COUNTIF('Calendario Octubre 2026'!$B$52:$B$56,"*-Fabian") -> 0
A22: Tony | B22: R3-04 | C22: 6 | F22: 6- | G22: 0 | H22: =COUNTIF('Calendario Octubre 2026'!$A$5:$N$58,"MAY-Tony") -> 0 | I22: =COUNTIF('Calendario Octubre 2026'!$A$5:$N$58,"TX-Tony") -> 0 | J22: =COUNTIF('Calendario Octubre 2026'!$A$5:$N$58,"UCQ-Tony") -> 6 | K22: =COUNTIF('Calendario Octubre 2026'!$A$5:$N$58,"PEQ-Tony") -> 0 | L22: =SUM(H22:K22) -> 6 | M22: =COUNTIF('Calendario Octubre 2026'!$B$5:$B$58,"*-Tony") -> 1 | N22: =COUNTIF('Calendario Octubre 2026'!$D$5:$D$58,"*-Tony") -> 0 | O22: =COUNTIF('Calendario Octubre 2026'!$F$5:$F$58,"*-Tony") -> 2 | P22: =COUNTIF('Calendario Octubre 2026'!$H$5:$H$58,"*-Tony") -> 0 | Q22: =COUNTIF('Calendario Octubre 2026'!$J$5:$J$58,"*-Tony") -> 1 | R22: =COUNTIF('Calendario Octubre 2026'!$L$5:$L$58,"*-Tony") -> 1 | S22: =COUNTIF('Calendario Octubre 2026'!$N$5:$N$58,"*-Tony") -> 1 | T22: =COUNTIF('Calendario Octubre 2026'!$B$25:$B$29,"*-Tony")+COUNTIF('Calendario Octubre 2026'!$N$43:$N$47,"*-Tony")+COUNTIF('Calendario Octubre 2026'!$B$52:$B$56,"*-Tony") -> 1
A23: Carlota | B23: R4-01 | D23: 4-5 | E23: 7 | F23: 0 | H23: =COUNTIF('Calendario Octubre 2026'!$A$5:$N$58,"MAY-Carlota") -> 5 | I23: =COUNTIF('Calendario Octubre 2026'!$A$5:$N$58,"TX-Carlota") -> 7 | J23: =COUNTIF('Calendario Octubre 2026'!$A$5:$N$58,"UCQ-Carlota") -> 0 | K23: =COUNTIF('Calendario Octubre 2026'!$A$5:$N$58,"PEQ-Carlota") -> 0 | L23: =SUM(H23:K23) -> 12 | M23: =COUNTIF('Calendario Octubre 2026'!$B$5:$B$58,"*-Carlota") -> 1 | N23: =COUNTIF('Calendario Octubre 2026'!$D$5:$D$58,"*-Carlota") -> 2 | O23: =COUNTIF('Calendario Octubre 2026'!$F$5:$F$58,"*-Carlota") -> 2 | P23: =COUNTIF('Calendario Octubre 2026'!$H$5:$H$58,"*-Carlota") -> 2 | Q23: =COUNTIF('Calendario Octubre 2026'!$J$5:$J$58,"*-Carlota") -> 2 | R23: =COUNTIF('Calendario Octubre 2026'!$L$5:$L$58,"*-Carlota") -> 1 | S23: =COUNTIF('Calendario Octubre 2026'!$N$5:$N$58,"*-Carlota") -> 2 | T23: =COUNTIF('Calendario Octubre 2026'!$B$25:$B$29,"*-Carlota")+COUNTIF('Calendario Octubre 2026'!$N$43:$N$47,"*-Carlota")+COUNTIF('Calendario Octubre 2026'!$B$52:$B$56,"*-Carlota") -> 1
A24: Almudena | B24: R4-02 | D24: 4-5 | E24: 7 | F24: 0 | H24: =COUNTIF('Calendario Octubre 2026'!$A$5:$N$58,"MAY-Almudena") -> 5 | I24: =COUNTIF('Calendario Octubre 2026'!$A$5:$N$58,"TX-Almudena") -> 5 | J24: =COUNTIF('Calendario Octubre 2026'!$A$5:$N$58,"UCQ-Almudena") -> 0 | K24: =COUNTIF('Calendario Octubre 2026'!$A$5:$N$58,"PEQ-Almudena") -> 0 | L24: =SUM(H24:K24) -> 10 | M24: =COUNTIF('Calendario Octubre 2026'!$B$5:$B$58,"*-Almudena") -> 2 | N24: =COUNTIF('Calendario Octubre 2026'!$D$5:$D$58,"*-Almudena") -> 0 | O24: =COUNTIF('Calendario Octubre 2026'!$F$5:$F$58,"*-Almudena") -> 3 | P24: =COUNTIF('Calendario Octubre 2026'!$H$5:$H$58,"*-Almudena") -> 1 | Q24: =COUNTIF('Calendario Octubre 2026'!$J$5:$J$58,"*-Almudena") -> 1 | R24: =COUNTIF('Calendario Octubre 2026'!$L$5:$L$58,"*-Almudena") -> 2 | S24: =COUNTIF('Calendario Octubre 2026'!$N$5:$N$58,"*-Almudena") -> 1 | T24: =COUNTIF('Calendario Octubre 2026'!$B$25:$B$29,"*-Almudena")+COUNTIF('Calendario Octubre 2026'!$N$43:$N$47,"*-Almudena")+COUNTIF('Calendario Octubre 2026'!$B$52:$B$56,"*-Almudena") -> 1
A25: Ana R4 (Gaudioso) | B25: R4-03 | D25: 1-2 | E25: 4 | F25: 0 | H25: =COUNTIF('Calendario Octubre 2026'!$A$5:$N$58,"MAY-AnaR4") -> 1 | I25: =COUNTIF('Calendario Octubre 2026'!$A$5:$N$58,"TX-AnaR4") -> 7 | J25: =COUNTIF('Calendario Octubre 2026'!$A$5:$N$58,"UCQ-AnaR4") -> 0 | K25: =COUNTIF('Calendario Octubre 2026'!$A$5:$N$58,"PEQ-AnaR4") -> 0 | L25: =SUM(H25:K25) -> 8 | M25: =COUNTIF('Calendario Octubre 2026'!$B$5:$B$58,"*-AnaR4") -> 3 | N25: =COUNTIF('Calendario Octubre 2026'!$D$5:$D$58,"*-AnaR4") -> 0 | O25: =COUNTIF('Calendario Octubre 2026'!$F$5:$F$58,"*-AnaR4") -> 0 | P25: =COUNTIF('Calendario Octubre 2026'!$H$5:$H$58,"*-AnaR4") -> 2 | Q25: =COUNTIF('Calendario Octubre 2026'!$J$5:$J$58,"*-AnaR4") -> 1 | R25: =COUNTIF('Calendario Octubre 2026'!$L$5:$L$58,"*-AnaR4") -> 1 | S25: =COUNTIF('Calendario Octubre 2026'!$N$5:$N$58,"*-AnaR4") -> 1 | T25: =COUNTIF('Calendario Octubre 2026'!$B$25:$B$29,"*-AnaR4")+COUNTIF('Calendario Octubre 2026'!$N$43:$N$47,"*-AnaR4")+COUNTIF('Calendario Octubre 2026'!$B$52:$B$56,"*-AnaR4") -> 2
A26: Sandra | B26: R4-04 | D26: 4-5 | E26: 8 | F26: 0 | H26: =COUNTIF('Calendario Octubre 2026'!$A$5:$N$58,"MAY-Sandra") -> 5 | I26: =COUNTIF('Calendario Octubre 2026'!$A$5:$N$58,"TX-Sandra") -> 7 | J26: =COUNTIF('Calendario Octubre 2026'!$A$5:$N$58,"UCQ-Sandra") -> 0 | K26: =COUNTIF('Calendario Octubre 2026'!$A$5:$N$58,"PEQ-Sandra") -> 0 | L26: =SUM(H26:K26) -> 12 | M26: =COUNTIF('Calendario Octubre 2026'!$B$5:$B$58,"*-Sandra") -> 2 | N26: =COUNTIF('Calendario Octubre 2026'!$D$5:$D$58,"*-Sandra") -> 2 | O26: =COUNTIF('Calendario Octubre 2026'!$F$5:$F$58,"*-Sandra") -> 1 | P26: =COUNTIF('Calendario Octubre 2026'!$H$5:$H$58,"*-Sandra") -> 2 | Q26: =COUNTIF('Calendario Octubre 2026'!$J$5:$J$58,"*-Sandra") -> 1 | R26: =COUNTIF('Calendario Octubre 2026'!$L$5:$L$58,"*-Sandra") -> 3 | S26: =COUNTIF('Calendario Octubre 2026'!$N$5:$N$58,"*-Sandra") -> 1 | T26: =COUNTIF('Calendario Octubre 2026'!$B$25:$B$29,"*-Sandra")+COUNTIF('Calendario Octubre 2026'!$N$43:$N$47,"*-Sandra")+COUNTIF('Calendario Octubre 2026'!$B$52:$B$56,"*-Sandra") -> 1
A27: Isa | B27: R4-05 | D27: 4-5 | E27: 7 | F27: 0 | H27: =COUNTIF('Calendario Octubre 2026'!$A$5:$N$58,"MAY-Isa") -> 5 | I27: =COUNTIF('Calendario Octubre 2026'!$A$5:$N$58,"TX-Isa") -> 7 | J27: =COUNTIF('Calendario Octubre 2026'!$A$5:$N$58,"UCQ-Isa") -> 0 | K27: =COUNTIF('Calendario Octubre 2026'!$A$5:$N$58,"PEQ-Isa") -> 0 | L27: =SUM(H27:K27) -> 12 | M27: =COUNTIF('Calendario Octubre 2026'!$B$5:$B$58,"*-Isa") -> 2 | N27: =COUNTIF('Calendario Octubre 2026'!$D$5:$D$58,"*-Isa") -> 2 | O27: =COUNTIF('Calendario Octubre 2026'!$F$5:$F$58,"*-Isa") -> 1 | P27: =COUNTIF('Calendario Octubre 2026'!$H$5:$H$58,"*-Isa") -> 2 | Q27: =COUNTIF('Calendario Octubre 2026'!$J$5:$J$58,"*-Isa") -> 2 | R27: =COUNTIF('Calendario Octubre 2026'!$L$5:$L$58,"*-Isa") -> 1 | S27: =COUNTIF('Calendario Octubre 2026'!$N$5:$N$58,"*-Isa") -> 2 | T27: =COUNTIF('Calendario Octubre 2026'!$B$25:$B$29,"*-Isa")+COUNTIF('Calendario Octubre 2026'!$N$43:$N$47,"*-Isa")+COUNTIF('Calendario Octubre 2026'!$B$52:$B$56,"*-Isa") -> 1
A28: TOTAL | H28: =SUM(H3:H27) -> 31 | I28: =SUM(I3:I27) -> 33 | J28: =SUM(J3:J27) -> 33 | K28: =SUM(K3:K27) -> 66 | L28: =SUM(L3:L27) -> 163 | M28: =SUM(M3:M27) -> 25 | N28: =SUM(N3:N27) -> 20 | O28: =SUM(O3:O27) -> 20 | ... T28: =SUM(T3:T27) -> 15
A30: MAY/Tx: §8.5.1. ucq (REA): H-11 (cupo 6) y mensaje directo de Pablo (1-2 para el resto de R2). peq (QX-P) R1: mensaje directo de Pablo (3-4, Miriam 4-5). "F" = guardias en día festivo/puente (12 oct, 1 y 2 nov).

Sheet Mapa de bloqueos
A1: MAPA DE BLOQUEOS · quién NO está disponible cada día (1 oct – 2 nov 2026)
B2: Bloqueo declarado | K2: "Si se puede" (blando) | T2: Ana R4 · trabajo externo | AC2: Disponible
C3: J | D3: V | E3: S | F3: D | G3: L | H3: M | I3: M | J3: J | K3: V | L3: S | M3: D | N3: L | O3: M | P3: M | Q3: J | R3: V | S3: S | T3: D | U3: L | V3: M | W3: M | X3: J | Y3: V | Z3: S | AA3: D | AB3: L | AC3: M | AD3: M | AE3: J | AF3: V | AG3: S | AH3: D | AI3: L
A4: Residente | B4: ID | C4: 1 | D4: 2 | E4: 3 | F4: 4 | G4: 5 | H4: 6 | I4: 7 | J4: 8 | K4: 9 | L4: 10 | M4: 11 | N4: 12 | O4: 13 | P4: 14 | Q4: 15 | R4: 16 | S4: 17 | T4: 18 | U4: 19 | V4: 20 | W4: 21 | X4: 22 | Y4: 23 | Z4: 24 | AA4: 25 | AB4: 26 | AC4: 27 | AD4: 28 | AE4: 29 | AF4: 30 | AG4: 31 | AH4: 1N | AI4: 2N
A5: Rosario | B5: R1-01 | D5: X | E5: X | F5: X | W5: X | X5: X | Y5: X | Z5: X | AA5: X
A6: Cristina | B6: R1-02 | D6: X | E6: X | F6: X | Y6: X | Z6: X | AA6: X
A7: Miriam | B7: R1-03 | K7: X | L7: X | M7: X | Y7: X | Z7: X | AA7: X
A8: David | B8: R1-04 | Y8: X | Z8: X | AA8: X
A9: Mercedes | B9: R1-05 | D9: X | E9: X | F9: X | Y9: X | Z9: X | AA9: X
A10: Arturo | B10: R1-06 | Y10: X | Z10: X | AA10: X
A11: Aitor | B11: R1-07 | D11: X | E11: X | F11: X | Y11: X | Z11: X | AA11: X
A12: Fatima | B12: R1-08 | K12: X | L12: X | M12: X | Y12: X | Z12: X | AA12: X
A13: Tania | B13: R2-01 | L13: X
A14: Asis | B14: R2-02 | J14: X | K14: X | Y14: X | Z14: X | AA14: X
A15: Patricia R2 | B15: R2-03
A16: Eva | B16: R2-04 | C16: X | D16: X | E16: X | F16: X | G16: X | H16: X | I16: X | J16: X
A17: Emilio | B17: R2-05 | C17: X | AB17: X | AF17: X
A18: Antonio | B18: R2-06 | Q18: X | R18: X | S18: X | T18: X
A19: Ana R2 | B19: R2-07 | E19: X | F19: X | Y19: X | Z19: X | AA19: X
A20: Marc | B20: R2-08
A21: Patricia R3 | B21: R3-01 | J21: X | K21: X | L21: X | M21: X | N21: X
A22: Candela | B22: R3-02 | J22: X | K22: X | X22: X | Y22: X | Z22: X | AA22: X
A23: Fabian | B23: R3-03 | Z23: X | AA23: X
A24: Tony | B24: R3-04 | K24: X | L24: X | M24: X
A25: Carlota | B25: R4-01 | D25: ~ | E25: ~ | F25: ~ | M25: ~ | Y25: ~ | Z25: ~ | AA25: ~
A26: Almudena | B26: R4-02 | D26: X | E26: X | F26: X | K26: X | L26: X | M26: X | Q26: X | R26: X | S26: X | T26: X | U26: X | V26: X | W26: X
A27: Ana R4 (Gaudioso) | B27: R4-03 | C27: E | F27: E | I27: E | L27: E | O27: E | R27: ~ | S27: ~ | T27: E | W27: E | AA27: E | AD27: E
A28: Sandra | B28: R4-04 | AE28: X | AF28: X | AG28: X | AH28: X
A29: Isa | B29: R4-05 | E29: X | F29: X | P29: X | Q29: X | R29: X | S29: X | T29: X
A30: TOTAL bloqueados | C30: 3 | D30: 7 | E30: 8 | F30: 10 | G30: 1 | H30: 1 | I30: 2 | J30: 4 | K30: 7 | L30: 7 | M30: 6 | N30: 1 | O30: 1 | P30: 1 | Q30: 3 | R30: 4 | S30: 4 | T30: 4 | U30: 1 | V30: 1 | W30: 3 | X30: 2 | Y30: 12 | Z30: 13 | AA30: 14 | AB30: 1 | AC30: 0 | AD30: 1 | AE30: 1 | AF30: 2 | AG30: 1 | AH30: 1 | AI30: 0

Sheet Validación H-01 a H-18
A1: Validación de reglas duras (rellena el agente revisor-optimizador tras cada pasada)
A3: Regla | B3: Descripción | C3: Veredicto | D3: Detalle si ❌ (día · persona · qué pasa · qué debería pasar)
A4: H-01 | B4: Cobertura completa: cada día tiene exactamente 1 TX, 1 UCQ, 1 MAY y 2 PEQ. | C4: ⚠️ | D4: Comprobado automáticamente: 1 excepción documentada — MAY del 9 y 11 oct (viernes-domingo) queda SIN CUBRIR. Solo Sandra podía cubrir ambos días (única disponible), pero el compromiso Q-08 (sábado 10 + lunes 12) se lo impide vía H-03. Resto de días: 0 violaciones.
A5: H-02 | B5: Nadie ocupa más de un puesto el mismo día. | C5: ✅ | D5: Comprobado automáticamente sobre el cuadrante generado (0 violaciones).
A6: H-03 | B6: Saliente de guardia libra 24h (D+1 vacío). | C6: ✅ | D6: Comprobado automáticamente sobre el cuadrante generado (0 violaciones).
A7: H-04 | B7: Guardia en sábado (no puente) ⇒ libra domingo y lunes. | C7: ✅ | D7: Comprobado automáticamente sobre el cuadrante generado (0 violaciones).
A8: H-05 | B8: Pareja viernes-domingo: misma persona, mismo puesto, bloque indivisible. | C8: ⚠️ | D8: Comprobado automáticamente: misma excepción que H-01 (pareja viernes 9 + domingo 11 de MAY sin cubrir, ver detalle en H-01). Resto de parejas viernes-domingo: 0 violaciones.
A9: H-06 | B9: Exclusión de puentes: quien cubre Pilar (10-12 oct) no cubre Santos (31 oct-2 nov) y viceversa. | C9: ✅ | D9: Comprobado automáticamente sobre el cuadrante generado (0 violaciones).
A10: H-07 | B10: Sábado de puente ⇒ se une al lunes festivo (prevalece sobre H-04) en FDS-2 y FDS-5. | C10: ✅ | D10: Comprobado automáticamente sobre el cuadrante generado (0 violaciones).
A11: H-08 | B11: Se respetan vacaciones y bloqueos declarados. | C11: ✅ | D11: Comprobado automáticamente sobre el cuadrante generado (0 violaciones).
A12: H-09 | B12: Elegibilidad por puesto (§5) respetada en todas las asignaciones. | C12: ✅
A13: H-10 | B13: Bloqueos individuales de Ana R4 (H-10a a H-10d). | C13: ✅ | D13: Comprobado automáticamente sobre el cuadrante generado (0 violaciones de H-10a a H-10d). | E13: no se entiende q es'?
A14: H-11 | B14: Tania, Patricia R2, Fabián, Tony: mínimo 6 guardias UCQ cada uno. | C14: ✅ | D14: Comprobado automáticamente sobre el cuadrante generado (0 violaciones).
A15: H-12 | B15: Esos mismos cuatro: mínimo 2 fines de semana cada uno (concretado por H-16). | C15: ✅ | D15: Comprobado automáticamente sobre el cuadrante generado (0 violaciones).
A16: H-13 | B16: Todo residente hace al menos 1 fin de semana. | C16: ✅ | D16: Comprobado automáticamente sobre el cuadrante generado (0 violaciones).
A17: H-14 | B17: No hay TX la víspera de una guardia presencial. | C17: ✅ | D17: Comprobado automáticamente sobre el cuadrante generado (0 violaciones).
A18: H-15 | B18: Agrupación del TX de fin de semana: una sola persona por bloque, 1:1 con los 5 R4. | C18: ✅ | D18: Redefinido por Q-15 (el bloque de fin de semana empieza el viernes, no el sábado). Comprobado automáticamente: los 5 R4 cubren cada uno exactamente 1 fin de semana completo, 0 violaciones.
A19: H-16 | B19: Los cuatro de UCQ cubren un bloque V-D y un sábado suelto cada uno. | C19: ✅ | D19: Comprobado automáticamente sobre el cuadrante generado (0 violaciones). | G19: 1. en los puestos de quirofano, los pequeños si es posible evitar dos R1 juntos el mismo día.
A20: H-17 | B20: Bloqueos declarados respetados (§8bis). | C20: ✅ | D20: Comprobado automáticamente sobre el cuadrante generado (0 violaciones). | G20: 2. siempre que se tenga guardia es imposible estar de trasplante el dia previo, pero si que se podría el día de saliente ( sin embargo, es preferible evitarlo.
A21: H-18 | B21: Congreso R1 23-25 oct: los 8 R1 bloqueados, PEQ lo cubre R2. | C21: ✅ | D21: Comprobado automáticamente sobre el cuadrante generado (0 violaciones). | G21: 3. cuando alguien se haya bloqueado un día por vacaciones ese dia previo a las vacaciones si que puede estar de guardia de quirofano o de REA, pero no puede estar de localizada de trasplante.
A22: H-19 | B22: Vacaciones y TX del día previo: se permite presencial pero no TX el día antes de un bloqueo. | C22: ✅ | D22: Comprobado automáticamente sobre el cuadrante generado (0 violaciones).
A23: H-20 | B23: Tope de guardias totales por año: R1 4-5, R2 exactamente 6, R3 máximo 6, R4 sin tope. | C23: ✅ | D23: Comprobado automáticamente: R1 entre 4 y 5 (Rosario 4, resto 5); R2 exactamente 6 en las 8; R3 entre 5 y 6 (Patricia R3 y Candela 5, Fabián y Tony 6); R4 sin tope aplicado. 0 violaciones.
A24: H-21 | B24: Tope de fines de semana dentro de R2: máximo 2 por persona. | C24: ✅ | D24: Comprobado automáticamente: los 8 R2 tienen exactamente 2 fines de semana cada uno (bloques distintos, no días sueltos). 0 violaciones — Eva y Antonio ya no tienen 3.
A26: VEREDICTO GLOBAL:
A27: Veredicto | B27: VÁLIDO salvo 1 excepción documentada — MAY 9 y 11 oct sin cubrir (ver H-01/H-05). Todas las demás reglas H-01 a H-21: 0 violaciones, incluidos los nuevos topes de guardias totales (H-20) y fines de semana de R2 (H-21) confirmados el 2026-08-18.
A30: Puntuación de reglas blandas S-01 a S-07 (0-41, ver fuente de la verdad §7 para el detalle de cada métrica)
A31: Regla | B31: Qué mide | C31: Puntos | D31: Puntuación obtenida
A32: S-01 | B32: 5 guardias MAY por mayor | C32: 10 | D32: 10
A33: S-02 | B33: Reparto equitativo de fines de semana | C33: 10 | D33: 10
A34: S-03 | B34: 2º FDS en sábado si el 1º fue bloque V-D | C34: 6 | D34: 0
A35: S-04 | B35: Reparto equitativo del total de guardias | C35: 6 | D35: 6
A36: S-05 | B36: Separación mínima 3-4 días entre guardias | C36: 5 | D36: 0
A38: S-07 | B38: Rotar el mayor que supervisa | C38: 2 | D38: 0
B39: TOTAL | C39: =SUM(C29:C35) -> 32 | D39: =SUM(D29:D35) -> 26
A42: Log de excepciones (toda regla blanda relajada, con justificación)
A43: Fecha | B43: Regla relajada | C43: Justificación | D43: Decidido por
A44: 9-11 oct | B44: H-01 / H-05 (MAY viernes 9 + domingo 11) | C44: Solo Sandra podia cubrir ambos dias (unica disponible por bloqueos). El compromiso Q-08 (sabado 10 + lunes 12) le impide por H-03. Queda sin cubrir a falta de decision. | D44: Pendiente de Pablo
A45: todo el mes | B45: S-06 (evitar 2 R1 en PEQ el mismo dia) | C45: Aclaracion de Pablo aplicada como regla dura en el generador: 0 incidencias. | D45: Pablo (aclaracion previa)
A46: todo el mes | B46: H-19 (sin TX la vispera de vacaciones) | C46: Aclaracion de Pablo aplicada: 0 incidencias. | D46: Pablo (aclaracion previa)
A47: 18/08/2026 | B47: H-20/H-21 (topes de R1/R2/R2-findes) | C47: Version anterior tenia R1 en 2-3 guardias, R2 en 8, y Eva/Antonio con 3 findes. Corregido a R1 4-5, R2=6 exacto, R2 max 2 findes, segun confirmacion de Pablo por WhatsApp. | D47: Pablo (WhatsApp 18/08)

Sheet Bloqueos y vacaciones
A1: Bloqueos y vacaciones declarados — octubre 2026 (32 = 1 nov, 33 = 2 nov)
A2: Residente | B2: ID | C2: Bloqueos declarados
A3: Rosario | B3: R1-01 | C3: 2-4, 21-25
A4: Cristina | B4: R1-02 | C4: 2-4, 23-25
A5: Miriam | B5: R1-03 | C5: 9-11, 23-25
A6: David | B6: R1-04 | C6: 23-25
A7: Mercedes | B7: R1-05 | C7: 2-4, 23-25
A8: Arturo | B8: R1-06 | C8: 23-25
A9: Aitor | B9: R1-07 | C9: 2-4, 23-25
A10: Fatima | B10: R1-08 | C10: 9-11, 23-25
A11: Tania | B11: R2-01 | C11: 10
A12: Asis | B12: R2-02 | C12: 8-9, 23-25
A13: Patricia R2 | B13: R2-03 | C13: — (ninguno)
... A27: Isa | B27: R4-05 | C27: 3,4, 14-18 (duro)
A29: Parte de guardias externas — Ana Gaudioso García (R4-03)
A30: Fecha (oct) | B30: Turno | C30: Tipo
A31: 1 oct | B31: 24(T2) | C31: CHA
A32: 4 oct | B32: MT | C32: SVA
A33: 7 oct | B33: 24(T2) | C33: CHA
A34: 10 oct | B34: MT | C34: SVA
A35: 13 oct | B35: 24(T2) | C35: CHA
A36: 18 oct | B36: MT | C36: SVA
A37: 21 oct | B37: 24(T2) | C37: CHA
A38: 25 oct | B38: 24(T2) | C38: CHA
A39: 28 oct | B39: MT | C39: SVA

Sheet Preguntas pendientes (Q)
A1: Decisiones pendientes de la fuente de la verdad — resuélvelas aquí
A2: ID | B2: Pregunta | C2: Supuesto aplicado en este libro / Respuesta | D2: Impacto
A3: Q-04 | B3: ¿"UCQ" y "REA" son el mismo puesto? | C3: Asumido que sí (usado así en este libro) | D3: Medio
A4: Q-05 | B4: En puentes: ¿quien hace el sábado trabaja el lunes festivo (H-07) o libra (H-04)? | C4: Asumido H-07 (aplicado en el Calendario) | D4: Alto
A5: Q-07 | B5: ¿La TX genera libranza al día siguiente? | C5: SI | D5: Bajo
