Workbook

Sheet Léeme
B2: Growth OS — cómo funciona este fichero
B3: Este Excel es la interfaz de trabajo de un sistema cuya fuente de la verdad vive en el repositorio de GitHub (growth-os/data/*.yaml). El fichero se genera desde esos datos y se puede volver a importar, de modo que cada estado del portfolio queda versionado y es auditable.
B4: El ciclo de trabajo
B5: EL CICLO DE TRABAJO
B6: 1. Tú editas en Excel: estados, avances, gastos, fechas, KPIs, hitos. Sólo las columnas de fondo blanco.
B7: 2. Guardas el fichero en su carpeta de OneDrive/SharePoint.
B8: 3. Le dices al agente «sincroniza el Growth OS». El agente lee el Excel, actualiza los YAML del repo y hace commit: ahí queda el histórico.
B9: 4. Cuando hay cambios estructurales (nuevos departamentos, columnas, métricas o reglas de cálculo), el agente regenera el Excel y lo vuelve a subir.
B10: Reglas de oro
B11: REGLAS DE ORO
B12: No renombres las hojas ni las cabeceras de columna: el importador las busca por nombre.
B13: No escribas en las columnas marcadas con «ƒ» ni en las de fondo gris. Son fórmulas y se sobreescriben en cada regeneración.
... B46: Crítico / vencido / bloqueado

Sheet Dashboard
B2: Founderz · Growth OS | BJ2: =IF(AND(Proyectos!$A2<>"",OR(Proyectos!$H2="En riesgo",Proyectos!$H2="Bloqueado",Proyectos!$AB2>0,IF(Proyectos!$V2="",FALSE,Proyectos!$V2<-0.15))),BK2,"") | BK2: =IF(AND(Proyectos!$A2<>"",OR(Proyectos!$H2="En riesgo",Proyectos!$H2="Bloqueado",Proyectos!$AB2>0,IF(Proyectos!$V2="",FALSE,Proyectos!$V2<-0.15))),N(BK1)+1,N(BK1)) | BN2: =IF(AND(Hitos!$A2<>"",OR(Hitos!$L2="Vencido",Hitos!$L2="Esta semana",Hitos!$L2="Próximos 30 días")),BO2,"") | BO2: =IF(AND(Hitos!$A2<>"",OR(Hitos!$L2="Vencido",Hitos!$L2="Esta semana",Hitos!$L2="Próximos 30 días")),N(BO1)+1,N(BO1))
B3: Panel de dirección — portfolio de proyectos, KPIs e hitos. Todo lo que ves aquí se calcula desde las hojas Proyectos, KPIs y Hitos. | BJ3: =IF(AND(Proyectos!$A3<>"",OR(Proyectos!$H3="En riesgo",Proyectos!$H3="Bloqueado",Proyectos!$AB3>0,IF(Proyectos!$V3="",FALSE,Proyectos!$V3<-0.15))),BK3,"") | BK3: =IF(AND(Proyectos!$A3<>"",OR(Proyectos!$H3="En riesgo",Proyectos!$H3="Bloqueado",Proyectos!$AB3>0,IF(Proyectos!$V3="",FALSE,Proyectos!$V3<-0.15))),N(BK2)+1,N(BK2)) | BN3: =IF(AND(Hitos!$A3<>"",OR(Hitos!$L3="Vencido",Hitos!$L3="Esta semana",Hitos!$L3="Próximos 30 días")),BO3,"") | BO3: =IF(AND(Hitos!$A3<>"",OR(Hitos!$L3="Vencido",Hitos!$L3="Esta semana",Hitos!$L3="Próximos 30 días")),N(BO2)+1,N(BO2))
B4: ="Datos a fecha de "&TEXT(TODAY(),"dd/mm/yyyy") | BJ4: =IF(AND(Proyectos!$A4<>"",OR(Proyectos!$H4="En riesgo",Proyectos!$H4="Bloqueado",Proyectos!$AB4>0,IF(Proyectos!$V4="",FALSE,Proyectos!$V4<-0.15))),BK4,"") | BK4: =IF(AND(Proyectos!$A4<>"",OR(Proyectos!$H4="En riesgo",Proyectos!$H4="Bloqueado",Proyectos!$AB4>0,IF(Proyectos!$V4="",FALSE,Proyectos!$V4<-0.15))),N(BK3)+1,N(BK3)) | BN4: =IF(AND(Hitos!$A4<>"",OR(Hitos!$L4="Vencido",Hitos!$L4="Esta semana",Hitos!$L4="Próximos 30 días")),BO4,"") | BO4: =IF(AND(Hitos!$A4<>"",OR(Hitos!$L4="Vencido",Hitos!$L4="Esta semana",Hitos!$L4="Próximos 30 días")),N(BO3)+1,N(BO3))
BJ5: =IF(AND(Proyectos!$A5<>"",OR(Proyectos!$H5="En riesgo",Proyectos!$H5="Bloqueado",Proyectos!$AB5>0,IF(Proyectos!$V5="",FALSE,Proyectos!$V5<-0.15))),BK5,"") | BK5: =IF(AND(Proyectos!$A5<>"",OR(Proyectos!$H5="En riesgo",Proyectos!$H5="Bloqueado",Proyectos!$AB5>0,IF(Proyectos!$V5="",FALSE,Proyectos!$V5<-0.15))),N(BK4)+1,N(BK4)) | BN5: =IF(AND(Hitos!$A5<>"",OR(Hitos!$L5="Vencido",Hitos!$L5="Esta semana",Hitos!$L5="Próximos 30 días")),BO5,"") | BO5: =IF(AND(Hitos!$A5<>"",OR(Hitos!$L5="Vencido",Hitos!$L5="Esta semana",Hitos!$L5="Próximos 30 días")),N(BO4)+1,N(BO4))
B6: Proyectos totales | C6: Activos | D6: En riesgo o bloqueados | E6: Avance medio | F6: Presupuesto comprometido | G6: Gasto acumulado | H6: % presupuesto consumido | I6: Hitos vencidos | J6: KPIs en crítico | BJ6: =IF(AND(Proyectos!$A6<>"",OR(Proyectos!$H6="En riesgo",Proyectos!$H6="Bloqueado",Proyectos!$AB6>0,IF(Proyectos!$V6="",FALSE,Proyectos!$V6<-0.15))),BK6,"") | BK6: =IF(AND(Proyectos!$A6<>"",OR(Proyectos!$H6="En riesgo",Proyectos!$H6="Bloqueado",Proyectos!$AB6>0,IF(Proyectos!$V6="",FALSE,Proyectos!$V6<-0.15))),N(BK5)+1,N(BK5)) | BN6: =IF(AND(Hitos!$A6<>"",OR(Hitos!$L6="Vencido",Hitos!$L6="Esta semana",Hitos!$L6="Próximos 30 días")),BO6,"") | BO6: =IF(AND(Hitos!$A6<>"",OR(Hitos!$L6="Vencido",Hitos!$L6="Esta semana",Hitos!$L6="Próximos 30 días")),N(BO5)+1,N(BO5))
B7: =COUNTA(Proyectos!$A$2:$A$41) | C7: =COUNTIF(Proyectos!$H$2:$H$41,"En curso")+COUNTIF(Proyectos!$H$2:$H$41,"En riesgo")+COUNTIF(Proyectos!$H$2:$H$41,"Bloqueado") | D7: =COUNTIF(Proyectos!$H$2:$H$41,"En riesgo")+COUNTIF(Proyectos!$H$2:$H$41,"Bloqueado") | E7: =IFERROR(SUMPRODUCT((Proyectos!$A$2:$A$41<>"")*(Proyectos!$H$2:$H$41<>"Cancelado")*Proyectos!$L$2:$L$41)/SUMPRODUCT((Proyectos!$A$2:$A$41<>"")*(Proyectos!$H$2:$H$41<>"Cancelado")*1),"") | F7: =SUMPRODUCT((Proyectos!$H$2:$H$41<>"Cancelado")*Proyectos!$N$2:$N$41) | G7: =SUMPRODUCT((Proyectos!$H$2:$H$41<>"Cancelado")*Proyectos!$O$2:$O$41) | H7: =IFERROR(SUMPRODUCT((Proyectos!$H$2:$H$41<>"Cancelado")*Proyectos!$O$2:$O$41)/SUMPRODUCT((Proyectos!$H$2:$H$41<>"Cancelado")*Proyectos!$N$2:$N$41),"") | I7: =SUMPRODUCT((Hitos!$A$2:$A$81<>"")*(Hitos!$E$2:$E$81<>"")*(Hitos!$E$2:$E$81<TODAY())*(Hitos!$F$2:$F$81<>"Completado")*(Hitos!$F$2:$F$81<>"Cancelado")) | J7: =COUNTIF(KPIs!$O$2:$O$71,"Crítico") | BJ7: =IF(AND(Proyectos!$A7<>"",OR(Proyectos!$H7="En riesgo",Proyectos!$H7="Bloqueado",Proyectos!$AB7>0,IF(Proyectos!$V7="",FALSE,Proyectos!$V7<-0.15))),BK7,"") | BK7: =IF(AND(Proyectos!$A7<>"",OR(Proyectos!$H7="En riesgo",Proyectos!$H7="Bloqueado",Proyectos!$AB7>0,IF(Proyectos!$V7="",FALSE,Proyectos!$V7<-0.15))),N(BK6)+1,N(BK6)) | BN7: =IF(AND(Hitos!$A7<>"",OR(Hitos!$L7="Vencido",Hitos!$L7="Esta semana",Hitos!$L7="Próximos 30 días")),BO7,"") | BO7: =IF(AND(Hitos!$A7<>"",OR(Hitos!$L7="Vencido",Hitos!$L7="Esta semana",Hitos!$L7="Próximos 30 días")),N(BO6)+1,N(BO6))
BJ8: =IF(AND(Proyectos!$A8<>"",OR(Proyectos!$H8="En riesgo",Proyectos!$H8="Bloqueado",Proyectos!$AB8>0,IF(Proyectos!$V8="",FALSE,Proyectos!$V8<-0.15))),BK8,"") | BK8: =IF(AND(Proyectos!$A8<>"",OR(Proyectos!$H8="En riesgo",Proyectos!$H8="Bloqueado",Proyectos!$AB8>0,IF(Proyectos!$V8="",FALSE,Proyectos!$V8<-0.15))),N(BK7)+1,N(BK7)) | BN8: =IF(AND(Hitos!$A8<>"",OR(Hitos!$L8="Vencido",Hitos!$L8="Esta semana",Hitos!$L8="Próximos 30 días")),BO8,"") | BO8: =IF(AND(Hitos!$A8<>"",OR(Hitos!$L8="Vencido",Hitos!$L8="Esta semana",Hitos!$L8="Próximos 30 días")),N(BO7)+1,N(BO7))
BJ9: =IF(AND(Proyectos!$A9<>"",OR(Proyectos!$H9="En riesgo",Proyectos!$H9="Bloqueado",Proyectos!$AB9>0,IF(Proyectos!$V9="",FALSE,Proyectos!$V9<-0.15))),BK9,"") | BK9: =IF(AND(Proyectos!$A9<>"",OR(Proyectos!$H9="En riesgo",Proyectos!$H9="Bloqueado",Proyectos!$AB9>0,IF(Proyectos!$V9="",FALSE,Proyectos!$V9<-0.15))),N(BK8)+1,N(BK8)) | BN9: =IF(AND(Hitos!$A9<>"",OR(Hitos!$L9="Vencido",Hitos!$L9="Esta semana",Hitos!$L9="Próximos 30 días")),BO9,"") | BO9: =IF(AND(Hitos!$A9<>"",OR(Hitos!$L9="Vencido",Hitos!$L9="Esta semana",Hitos!$L9="Próximos 30 días")),N(BO8)+1,N(BO8))
B10: PORTFOLIO POR ESTADO | BJ10: =IF(AND(Proyectos!$A10<>"",OR(Proyectos!$H10="En riesgo",Proyectos!$H10="Bloqueado",Proyectos!$AB10>0,IF(Proyectos!$V10="",FALSE,Proyectos!$V10<-0.15))),BK10,"") | BK10: =IF(AND(Proyectos!$A10<>"",OR(Proyectos!$H10="En riesgo",Proyectos!$H10="Bloqueado",Proyectos!$AB10>0,IF(Proyectos!$V10="",FALSE,Proyectos!$V10<-0.15))),N(BK9)+1,N(BK9)) | BN10: =IF(AND(Hitos!$A10<>"",OR(Hitos!$L10="Vencido",Hitos!$L10="Esta semana",Hitos!$L10="Próximos 30 días")),BO10,"") | BO10: =IF(AND(Hitos!$A10<>"",OR(Hitos!$L10="Vencido",Hitos!$L10="Esta semana",Hitos!$L10="Próximos 30 días")),N(BO9)+1,N(BO9))
B11: Estado | C11: Proyectos | D11: % del total | E11: Presupuesto € | F11: Gasto € | G11: Avance medio | BJ11: =IF(AND(Proyectos!$A11<>"",OR(Proyectos!$H11="En riesgo",Proyectos!$H11="Bloqueado",Proyectos!$AB11>0,IF(Proyectos!$V11="",FALSE,Proyectos!$V11<-0.15))),BK11,"") | BK11: =IF(AND(Proyectos!$A11<>"",OR(Proyectos!$H11="En riesgo",Proyectos!$H11="Bloqueado",Proyectos!$AB11>0,IF(Proyectos!$V11="",FALSE,Proyectos!$V11<-0.15))),N(BK10)+1,N(BK10)) | BN11: =IF(AND(Hitos!$A11<>"",OR(Hitos!$L11="Vencido",Hitos!$L11="Esta semana",Hitos!$L11="Próximos 30 días")),BO11,"") | BO11: =IF(AND(Hitos!$A11<>"",OR(Hitos!$L11="Vencido",Hitos!$L11="Esta semana",Hitos!$L11="Próximos 30 días")),N(BO10)+1,N(BO10))
B12: Backlog | C12: =COUNTIF(Proyectos!$H$2:$H$41,$B12) | D12: =IFERROR($C12/SUM($C$12:$C$17),"") | E12: =SUMIF(Proyectos!$H$2:$H$41,$B12,Proyectos!$N$2:$N$41) | F12: =SUMIF(Proyectos!$H$2:$H$41,$B12,Proyectos!$O$2:$O$41) | G12: =IFERROR(AVERAGEIF(Proyectos!$H$2:$H$41,$B12,Proyectos!$L$2:$L$41),"") | BJ12: =IF(AND(Proyectos!$A12<>"",OR(Proyectos!$H12="En riesgo",Proyectos!$H12="Bloqueado",Proyectos!$AB12>0,IF(Proyectos!$V12="",FALSE,Proyectos!$V12<-0.15))),BK12,"") | BK12: =IF(AND(Proyectos!$A12<>"",OR(Proyectos!$H12="En riesgo",Proyectos!$H12="Bloqueado",Proyectos!$AB12>0,IF(Proyectos!$V12="",FALSE,Proyectos!$V12<-0.15))),N(BK11)+1,N(BK11)) | BN12: =IF(AND(Hitos!$A12<>"",OR(Hitos!$L12="Vencido",Hitos!$L12="Esta semana",Hitos!$L12="Próximos 30 días")),BO12,"") | BO12: =IF(AND(Hitos!$A12<>"",OR(Hitos!$L12="Vencido",Hitos!$L12="Esta semana",Hitos!$L12="Próximos 30 días")),N(BO11)+1,N(BO11))
B13: En curso | C13: =COUNTIF(Proyectos!$H$2:$H$41,$B13) | D13: =IFERROR($C13/SUM($C$12:$C$17),"") | E13: =SUMIF(Proyectos!$H$2:$H$41,$B13,Proyectos!$N$2:$N$41) | F13: =SUMIF(Proyectos!$H$2:$H$41,$B13,Proyectos!$O$2:$O$41) | G13: =IFERROR(AVERAGEIF(Proyectos!$H$2:$H$41,$B13,Proyectos!$L$2:$L$41),"") | BJ13: =IF(AND(Proyectos!$A13<>"",OR(Proyectos!$H13="En riesgo",Proyectos!$H13="Bloqueado",Proyectos!$AB13>0,IF(Proyectos!$V13="",FALSE,Proyectos!$V13<-0.15))),BK13,"") | BK13: =IF(AND(Proyectos!$A13<>"",OR(Proyectos!$H13="En riesgo",Proyectos!$H13="Bloqueado",Proyectos!$AB13>0,IF(Proyectos!$V13="",FALSE,Proyectos!$V13<-0.15))),N(BK12)+1,N(BK12)) | BN13: =IF(AND(Hitos!$A13<>"",OR(Hitos!$L13="Vencido",Hitos!$L13="Esta semana",Hitos!$L13="Próximos 30 días")),BO13,"") | BO13: =IF(AND(Hitos!$A13<>"",OR(Hitos!$L13="Vencido",Hitos!$L13="Esta semana",Hitos!$L13="Próximos 30 días")),N(BO12)+1,N(BO12))
B14: En riesgo | C14: =COUNTIF(Proyectos!$H$2:$H$41,$B14) | D14: =IFERROR($C14/SUM($C$12:$C$17),"") | E14: =SUMIF(Proyectos!$H$2:$H$41,$B14,Proyectos!$N$2:$N$41) | F14: =SUMIF(Proyectos!$H$2:$H$41,$B14,Proyectos!$O$2:$O$41) | G14: =IFERROR(AVERAGEIF(Proyectos!$H$2:$H$41,$B14,Proyectos!$L$2:$L$41),"") | BJ14: =IF(AND(Proyectos!$A14<>"",OR(Proyectos!$H14="En riesgo",Proyectos!$H14="Bloqueado",Proyectos!$AB14>0,IF(Proyectos!$V14="",FALSE,Proyectos!$V14<-0.15))),BK14,"") | BK14: =IF(AND(Proyectos!$A14<>"",OR(Proyectos!$H14="En riesgo",Proyectos!$H14="Bloqueado",Proyectos!$AB14>0,IF(Proyectos!$V14="",FALSE,Proyectos!$V14<-0.15))),N(BK13)+1,N(BK13)) | BN14: =IF(AND(Hitos!$A14<>"",OR(Hitos!$L14="Vencido",Hitos!$L14="Esta semana",Hitos!$L14="Próximos 30 días")),BO14,"") | BO14: =IF(AND(Hitos!$A14<>"",OR(Hitos!$L14="Vencido",Hitos!$L14="Esta semana",Hitos!$L14="Próximos 30 días")),N(BO13)+1,N(BO13))
B15: Bloqueado | C15: =COUNTIF(Proyectos!$H$2:$H$41,$B15) | D15: =IFERROR($C15/SUM($C$12:$C$17),"") | E15: =SUMIF(Proyectos!$H$2:$H$41,$B15,Proyectos!$N$2:$N$41) | F15: =SUMIF(Proyectos!$H$2:$H$41,$B15,Proyectos!$O$2:$O$41) | G15: =IFERROR(AVERAGEIF(Proyectos!$H$2:$H$41,$B15,Proyectos!$L$2:$L$41),"") | BJ15: =IF(AND(Proyectos!$A15<>"",OR(Proyectos!$H15="En riesgo",Proyectos!$H15="Bloqueado",Proyectos!$AB15>0,IF(Proyectos!$V15="",FALSE,Proyectos!$V15<-0.15))),BK15,"") | BK15: =IF(AND(Proyectos!$A15<>"",OR(Proyectos!$H15="En riesgo",Proyectos!$H15="Bloqueado",Proyectos!$AB15>0,IF(Proyectos!$V15="",FALSE,Proyectos!$V15<-0.15))),N(BK14)+1,N(BK14)) | BN15: =IF(AND(Hitos!$A15<>"",OR(Hitos!$L15="Vencido",Hitos!$L15="Esta semana",Hitos!$L15="Próximos 30 días")),BO15,"") | BO15: =IF(AND(Hitos!$A15<>"",OR(Hitos!$L15="Vencido",Hitos!$L15="Esta semana",Hitos!$L15="Próximos 30 días")),N(BO14)+1,N(BO14))
B16: Completado | C16: =COUNTIF(Proyectos!$H$2:$H$41,$B16) | D16: =IFERROR($C16/SUM($C$12:$C$17),"") | E16: =SUMIF(Proyectos!$H$2:$H$41,$B16,Proyectos!$N$2:$N$41) | F16: =SUMIF(Proyectos!$H$2:$H$41,$B16,Proyectos!$O$2:$O$41) | G16: =IFERROR(AVERAGEIF(Proyectos!$H$2:$H$41,$B16,Proyectos!$L$2:$L$41),"") | BJ16: =IF(AND(Proyectos!$A16<>"",OR(Proyectos!$H16="En riesgo",Proyectos!$H16="Bloqueado",Proyectos!$AB16>0,IF(Proyectos!$V16="",FALSE,Proyectos!$V16<-0.15))),BK16,"") | BK16: =IF(AND(Proyectos!$A16<>"",OR(Proyectos!$H16="En riesgo",Proyectos!$H16="Bloqueado",Proyectos!$AB16>0,IF(Proyectos!$V16="",FALSE,Proyectos!$V16<-0.15))),N(BK15)+1,N(BK15)) | BN16: =IF(AND(Hitos!$A16<>"",OR(Hitos!$L16="Vencido",Hitos!$L16="Esta semana",Hitos!$L16="Próximos 30 días")),BO16,"") | BO16: =IF(AND(Hitos!$A16<>"",OR(Hitos!$L16="Vencido",Hitos!$L16="Esta semana",Hitos!$L16="Próximos 30 días")),N(BO15)+1,N(BO15))
B17: Cancelado | C17: =COUNTIF(Proyectos!$H$2:$H$41,$B17) | D17: =IFERROR($C17/SUM($C$12:$C$17),"") | E17: =SUMIF(Proyectos!$H$2:$H$41,$B17,Proyectos!$N$2:$N$41) | F17: =SUMIF(Proyectos!$H$2:$H$41,$B17,Proyectos!$O$2:$O$41) | G17: =IFERROR(AVERAGEIF(Proyectos!$H$2:$H$41,$B17,Proyectos!$L$2:$L$41),"") | BJ17: =IF(AND(Proyectos!$A17<>"",OR(Proyectos!$H17="En riesgo",Proyectos!$H17="Bloqueado",Proyectos!$AB17>0,IF(Proyectos!$V17="",FALSE,Proyectos!$V17<-0.15))),BK17,"") | BK17: =IF(AND(Proyectos!$A17<>"",OR(Proyectos!$H17="En riesgo",Proyectos!$H17="Bloqueado",Proyectos!$AB17>0,IF(Proyectos!$V17="",FALSE,Proyectos!$V17<-0.15))),N(BK16)+1,N(BK16)) | BN17: =IF(AND(Hitos!$A17<>"",OR(Hitos!$L17="Vencido",Hitos!$L17="Esta semana",Hitos!$L17="Próximos 30 días")),BO17,"") | BO17: =IF(AND(Hitos!$A17<>"",OR(Hitos!$L17="Vencido",Hitos!$L17="Esta semana",Hitos!$L17="Próximos 30 días")),N(BO16)+1,N(BO16))
BJ18: =IF(AND(Proyectos!$A18<>"",OR(Proyectos!$H18="En riesgo",Proyectos!$H18="Bloqueado",Proyectos!$AB18>0,IF(Proyectos!$V18="",FALSE,Proyectos!$V18<-0.15))),BK18,"") | BK18: =IF(AND(Proyectos!$A18<>"",OR(Proyectos!$H18="En riesgo",Proyectos!$H18="Bloqueado",Proyectos!$AB18>0,IF(Proyectos!$V18="",FALSE,Proyectos!$V18<-0.15))),N(BK17)+1,N(BK17)) | BN18: =IF(AND(Hitos!$A18<>"",OR(Hitos!$L18="Vencido",Hitos!$L18="Esta semana",Hitos!$L18="Próximos 30 días")),BO18,"") | BO18: =IF(AND(Hitos!$A18<>"",OR(Hitos!$L18="Vencido",Hitos!$L18="Esta semana",Hitos!$L18="Próximos 30 días")),N(BO17)+1,N(BO17))
B19: PORTFOLIO POR DEPARTAMENTO | BJ19: =IF(AND(Proyectos!$A19<>"",OR(Proyectos!$H19="En riesgo",Proyectos!$H19="Bloqueado",Proyectos!$AB19>0,IF(Proyectos!$V19="",FALSE,Proyectos!$V19<-0.15))),BK19,"") | BK19: =IF(AND(Proyectos!$A19<>"",OR(Proyectos!$H19="En riesgo",Proyectos!$H19="Bloqueado",Proyectos!$AB19>0,IF(Proyectos!$V19="",FALSE,Proyectos!$V19<-0.15))),N(BK18)+1,N(BK18)) | BN19: =IF(AND(Hitos!$A19<>"",OR(Hitos!$L19="Vencido",Hitos!$L19="Esta semana",Hitos!$L19="Próximos 30 días")),BO19,"") | BO19: =IF(AND(Hitos!$A19<>"",OR(Hitos!$L19="Vencido",Hitos!$L19="Esta semana",Hitos!$L19="Próximos 30 días")),N(BO18)+1,N(BO18))
B20: Departamento | C20: Proyectos | D20: Activos | E20: Presupuesto € | F20: Gasto € | G20: % consumido | H20: Avance medio | I20: Hitos vencidos | J20: KPIs críticos | BJ20: =IF(AND(Proyectos!$A20<>"",OR(Proyectos!$H20="En riesgo",Proyectos!$H20="Bloqueado",Proyectos!$AB20>0,IF(Proyectos!$V20="",FALSE,Proyectos!$V20<-0.15))),BK20,"") | BK20: =IF(AND(Proyectos!$A20<>"",OR(Proyectos!$H20="En riesgo",Proyectos!$H20="Bloqueado",Proyectos!$AB20>0,IF(Proyectos!$V20="",FALSE,Proyectos!$V20<-0.15))),N(BK19)+1,N(BK19)) | BN20: =IF(AND(Hitos!$A20<>"",OR(Hitos!$L20="Vencido",Hitos!$L20="Esta semana",Hitos!$L20="Próximos 30 días")),BO20,"") | BO20: =IF(AND(Hitos!$A20<>"",OR(Hitos!$L20="Vencido",Hitos!$L20="Esta semana",Hitos!$L20="Próximos 30 días")),N(BO19)+1,N(BO19))
B21: Growth | C21: =COUNTIF(Proyectos!$C$2:$C$41,$B21) | D21: =COUNTIFS(Proyectos!$C$2:$C$41,$B21,Proyectos!$H$2:$H$41,"En curso")+COUNTIFS(Proyectos!$C$2:$C$41,$B21,Proyectos!$H$2:$H$41,"En riesgo")+COUNTIFS(Proyectos!$C$2:$C$41,$B21,Proyectos!$H$2:$H$41,"Bloqueado") | E21: =SUMIF(Proyectos!$C$2:$C$41,$B21,Proyectos!$N$2:$N$41) | F21: =SUMIF(Proyectos!$C$2:$C$41,$B21,Proyectos!$O$2:$O$41) | G21: =IFERROR(F21/E21,"") | H21: =IFERROR(AVERAGEIF(Proyectos!$C$2:$C$41,$B21,Proyectos!$L$2:$L$41),"") | I21: =SUMPRODUCT((Hitos!$I$2:$I$81=$B21)*(Hitos!$E$2:$E$81<>"")*(Hitos!$E$2:$E$81<TODAY())*(Hitos!$F$2:$F$81<>"Completado")*(Hitos!$F$2:$F$81<>"Cancelado")) | J21: =COUNTIFS(KPIs!$L$2:$L$71,$B21,KPIs!$O$2:$O$71,"Crítico") | BJ21: =IF(AND(Proyectos!$A21<>"",OR(Proyectos!$H21="En riesgo",Proyectos!$H21="Bloqueado",Proyectos!$AB21>0,IF(Proyectos!$V21="",FALSE,Proyectos!$V21<-0.15))),BK21,"") | BK21: =IF(AND(Proyectos!$A21<>"",OR(Proyectos!$H21="En riesgo",Proyectos!$H21="Bloqueado",Proyectos!$AB21>0,IF(Proyectos!$V21="",FALSE,Proyectos!$V21<-0.15))),N(BK20)+1,N(BK20)) | BN21: =IF(AND(Hitos!$A21<>"",OR(Hitos!$L21="Vencido",Hitos!$L21="Esta semana",Hitos!$L21="Próximos 30 días")),BO21,"") | BO21: =IF(AND(Hitos!$A21<>"",OR(Hitos!$L21="Vencido",Hitos!$L21="Esta semana",Hitos!$L21="Próximos 30 días")),N(BO20)+1,N(BO20))
BJ22: =IF(AND(Proyectos!$A22<>"",OR(Proyectos!$H22="En riesgo",Proyectos!$H22="Bloqueado",Proyectos!$AB22>0,IF(Proyectos!$V22="",FALSE,Proyectos!$V22<-0.15))),BK22,"") | BK22: =IF(AND(Proyectos!$A22<>"",OR(Proyectos!$H22="En riesgo",Proyectos!$H22="Bloqueado",Proyectos!$AB22>0,IF(Proyectos!$V22="",FALSE,Proyectos!$V22<-0.15))),N(BK21)+1,N(BK21)) | BN22: =IF(AND(Hitos!$A22<>"",OR(Hitos!$L22="Vencido",Hitos!$L22="Esta semana",Hitos!$L22="Próximos 30 días")),BO22,"") | BO22: =IF(AND(Hitos!$A22<>"",OR(Hitos!$L22="Vencido",Hitos!$L22="Esta semana",Hitos!$L22="Próximos 30 días")),N(BO21)+1,N(BO21))
B23: ZOOM POR SUBÁREA | BJ23: =IF(AND(Proyectos!$A23<>"",OR(Proyectos!$H23="En riesgo",Proyectos!$H23="Bloqueado",Proyectos!$AB23>0,IF(Proyectos!$V23="",FALSE,Proyectos!$V23<-0.15))),BK23,"") | BK23: =IF(AND(Proyectos!$A23<>"",OR(Proyectos!$H23="En riesgo",Proyectos!$H23="Bloqueado",Proyectos!$AB23>0,IF(Proyectos!$V23="",FALSE,Proyectos!$V23<-0.15))),N(BK22)+1,N(BK22)) | BN23: =IF(AND(Hitos!$A23<>"",OR(Hitos!$L23="Vencido",Hitos!$L23="Esta semana",Hitos!$L23="Próximos 30 días")),BO23,"") | BO23: =IF(AND(Hitos!$A23<>"",OR(Hitos!$L23="Vencido",Hitos!$L23="Esta semana",Hitos!$L23="Próximos 30 días")),N(BO22)+1,N(BO22))
B24: Departamento | C24: Subárea | D24: Proyectos | E24: Activos | F24: Presupuesto € | G24: Gasto € | H24: % consumido | I24: Avance medio | J24: Hitos vencidos | K24: KPIs críticos | BJ24: =IF(AND(Proyectos!$A24<>"",OR(Proyectos!$H24="En riesgo",Proyectos!$H24="Bloqueado",Proyectos!$AB24>0,IF(Proyectos!$V24="",FALSE,Proyectos!$V24<-0.15))),BK24,"") | BK24: =IF(AND(Proyectos!$A24<>"",OR(Proyectos!$H24="En riesgo",Proyectos!$H24="Bloqueado",Proyectos!$AB24>0,IF(Proyectos!$V24="",FALSE,Proyectos!$V24<-0.15))),N(BK23)+1,N(BK23)) | BN24: =IF(AND(Hitos!$A24<>"",OR(Hitos!$L24="Vencido",Hitos!$L24="Esta semana",Hitos!$L24="Próximos 30 días")),BO24,"") | BO24: =IF(AND(Hitos!$A24<>"",OR(Hitos!$L24="Vencido",Hitos!$L24="Esta semana",Hitos!$L24="Próximos 30 días")),N(BO23)+1,N(BO23))
B25: Growth | C25: Paid Media | D25: =COUNTIF(Proyectos!$D$2:$D$41,$C25) | E25: =COUNTIFS(Proyectos!$D$2:$D$41,$C25,Proyectos!$H$2:$H$41,"En curso")+COUNTIFS(Proyectos!$D$2:$D$41,$C25,Proyectos!$H$2:$H$41,"En riesgo")+COUNTIFS(Proyectos!$D$2:$D$41,$C25,Proyectos!$H$2:$H$41,"Bloqueado") | F25: =SUMIF(Proyectos!$D$2:$D$41,$C25,Proyectos!$N$2:$N$41) | G25: =SUMIF(Proyectos!$D$2:$D$41,$C25,Proyectos!$O$2:$O$41) | H25: =IFERROR(G25/F25,"") | I25: =IFERROR(AVERAGEIF(Proyectos!$D$2:$D$41,$C25,Proyectos!$L$2:$L$41),"") | J25: =SUMPRODUCT((Hitos!$J$2:$J$81=$C25)*(Hitos!$E$2:$E$81<>"")*(Hitos!$E$2:$E$81<TODAY())*(Hitos!$F$2:$F$81<>"Completado")*(Hitos!$F$2:$F$81<>"Cancelado")) | K25: =COUNTIFS(KPIs!$M$2:$M$71,$C25,KPIs!$O$2:$O$71,"Crítico") | BJ25: =IF(AND(Proyectos!$A25<>"",OR(Proyectos!$H25="En riesgo",Proyectos!$H25="Bloqueado",Proyectos!$AB25>0,IF(Proyectos!$V25="",FALSE,Proyectos!$V25<-0.15))),BK25,"") | BK25: =IF(AND(Proyectos!$A25<>"",OR(Proyectos!$H25="En riesgo",Proyectos!$H25="Bloqueado",Proyectos!$AB25>0,IF(Proyectos!$V25="",FALSE,Proyectos!$V25<-0.15))),N(BK24)+1,N(BK24)) | BN25: =IF(AND(Hitos!$A25<>"",OR(Hitos!$L25="Vencido",Hitos!$L25="Esta semana",Hitos!$L25="Próximos 30 días")),BO25,"") | BO25: =IF(AND(Hitos!$A25<>"",OR(Hitos!$L25="Vencido",Hitos!$L25="Esta semana",Hitos!$L25="Próximos 30 días")),N(BO24)+1,N(BO24))
B26: Growth | C26: SEO & Contenido | D26: =COUNTIF(Proyectos!$D$2:$D$41,$C26) | E26: =COUNTIFS(Proyectos!$D$2:$D$41,$C26,Proyectos!$H$2:$H$41,"En curso")+COUNTIFS(Proyectos!$D$2:$D$41,$C26,Proyectos!$H$2:$H$41,"En riesgo")+COUNTIFS(Proyectos!$D$2:$D$41,$C26,Proyectos!$H$2:$H$41,"Bloqueado") | F26: =SUMIF(Proyectos!$D$2:$D$41,$C26,Proyectos!$N$2:$N$41) | G26: =SUMIF(Proyectos!$D$2:$D$41,$C26,Proyectos!$O$2:$O$41) | H26: =IFERROR(G26/F26,"") | I26: =IFERROR(AVERAGEIF(Proyectos!$D$2:$D$41,$C26,Proyectos!$L$2:$L$41),"") | J26: =SUMPRODUCT((Hitos!$J$2:$J$81=$C26)*(Hitos!$E$2:$E$81<>"")*(Hitos!$E$2:$E$81<TODAY())*(Hitos!$F$2:$F$81<>"Completado")*(Hitos!$F$2:$F$81<>"Cancelado")) | K26: =COUNTIFS(KPIs!$M$2:$M$71,$C26,KPIs!$O$2:$O$71,"Crítico") | BJ26: =IF(AND(Proyectos!$A26<>"",OR(Proyectos!$H26="En riesgo",Proyectos!$H26="Bloqueado",Proyectos!$AB26>0,IF(Proyectos!$V26="",FALSE,Proyectos!$V26<-0.15))),BK26,"") | BK26: =IF(AND(Proyectos!$A26<>"",OR(Proyectos!$H26="En riesgo",Proyectos!$H26="Bloqueado",Proyectos!$AB26>0,IF(Proyectos!$V26="",FALSE,Proyectos!$V26<-0.15))),N(BK25)+1,N(BK25)) | BN26: =IF(AND(Hitos!$A26<>"",OR(Hitos!$L26="Vencido",Hitos!$L26="Esta semana",Hitos!$L26="Próximos 30 días")),BO26,"") | BO26: =IF(AND(Hitos!$A26<>"",OR(Hitos!$L26="Vencido",Hitos!$L26="Esta semana",Hitos!$L26="Próximos 30 días")),N(BO25)+1,N(BO25))
B27: Growth | C27: CRO & Web | D27: =COUNTIF(Proyectos!$D$2:$D$41,$C27) | E27: =COUNTIFS(Proyectos!$D$2:$D$41,$C27,Proyectos!$H$2:$H$41,"En curso")+COUNTIFS(Proyectos!$D$2:$D$41,$C27,Proyectos!$H$2:$H$41,"En riesgo")+COUNTIFS(Proyectos!$D$2:$D$41,$C27,Proyectos!$H$2:$H$41,"Bloqueado") | F27: =SUMIF(Proyectos!$D$2:$D$41,$C27,Proyectos!$N$2:$N$41) | G27: =SUMIF(Proyectos!$D$2:$D$41,$C27,Proyectos!$O$2:$O$41) | H27: =IFERROR(G27/F27,"") | I27: =IFERROR(AVERAGEIF(Proyectos!$D$2:$D$41,$C27,Proyectos!$L$2:$L$41),"") | J27: =SUMPRODUCT((Hitos!$J$2:$J$81=$C27)*(Hitos!$E$2:$E$81<>"")*(Hitos!$E$2:$E$81<TODAY())*(Hitos!$F$2:$F$81<>"Completado")*(Hitos!$F$2:$F$81<>"Cancelado")) | K27: =COUNTIFS(KPIs!$M$2:$M$71,$C27,KPIs!$O$2:$O$71,"Crítico") | BJ27: =IF(AND(Proyectos!$A27<>"",OR(Proyectos!$H27="En riesgo",Proyectos!$H27="Bloqueado",Proyectos!$AB27>0,IF(Proyectos!$V27="",FALSE,Proyectos!$V27<-0.15))),BK27,"") | BK27: =IF(AND(Proyectos!$A27<>"",OR(Proyectos!$H27="En riesgo",Proyectos!$H27="Bloqueado",Proyectos!$AB27>0,IF(Proyectos!$V27="",FALSE,Proyectos!$V27<-0.15))),N(BK26)+1,N(BK26)) | BN27: =IF(AND(Hitos!$A27<>"",OR(Hitos!$L27="Vencido",Hitos!$L27="Esta semana",Hitos!$L27="Próximos 30 días")),BO27,"") | BO27: =IF(AND(Hitos!$A27<>"",OR(Hitos!$L27="Vencido",Hitos!$L27="Esta semana",Hitos!$L27="Próximos 30 días")),N(BO26)+1,N(BO26))
B28: Growth | C28: Lifecycle & CRM | D28: =COUNTIF(Proyectos!$D$2:$D$41,$C28) | E28: =COUNTIFS(Proyectos!$D$2:$D$41,$C28,Proyectos!$H$2:$H$41,"En curso")+COUNTIFS(Proyectos!$D$2:$D$41,$C28,Proyectos!$H$2:$H$41,"En riesgo")+COUNTIFS(Proyectos!$D$2:$D$41,$C28,Proyectos!$H$2:$H$41,"Bloqueado") | F28: =SUMIF(Proyectos!$D$2:$D$41,$C28,Proyectos!$N$2:$N$41) | G28: =SUMIF(Proyectos!$D$2:$D$41,$C28,Proyectos!$O$2:$O$41) | H28: =IFERROR(G28/F28,"") | I28: =IFERROR(AVERAGEIF(Proyectos!$D$2:$D$41,$C28,Proyectos!$L$2:$L$41),"") | J28: =SUMPRODUCT((Hitos!$J$2:$J$81=$C28)*(Hitos!$E$2:$E$81<>"")*(Hitos!$E$2:$E$81<TODAY())*(Hitos!$F$2:$F$81<>"Completado")*(Hitos!$F$2:$F$81<>"Cancelado")) | K28: =COUNTIFS(KPIs!$M$2:$M$71,$C28,KPIs!$O$2:$O$71,"Crítico") | BJ28: =IF(AND(Proyectos!$A28<>"",OR(Proyectos!$H28="En riesgo",Proyectos!$H28="Bloqueado",Proyectos!$AB28>0,IF(Proyectos!$V28="",FALSE,Proyectos!$V28<-0.15))),BK28,"") | BK28: =IF(AND(Proyectos!$A28<>"",OR(Proyectos!$H28="En riesgo",Proyectos!$H28="Bloqueado",Proyectos!$AB28>0,IF(Proyectos!$V28="",FALSE,Proyectos!$V28<-0.15))),N(BK27)+1,N(BK27)) | BN28: =IF(AND(Hitos!$A28<>"",OR(Hitos!$L28="Vencido",Hitos!$L28="Esta semana",Hitos!$L28="Próximos 30 días")),BO28,"") | BO28: =IF(AND(Hitos!$A28<>"",OR(Hitos!$L28="Vencido",Hitos!$L28="Esta semana",Hitos!$L28="Próximos 30 días")),N(BO27)+1,N(BO27))
B29: Growth | C29: Partnerships & Afiliación | D29: =COUNTIF(Proyectos!$D$2:$D$41,$C29) | E29: =COUNTIFS(Proyectos!$D$2:$D$41,$C29,Proyectos!$H$2:$H$41,"En curso")+COUNTIFS(Proyectos!$D$2:$D$41,$C29,Proyectos!$H$2:$H$41,"En riesgo")+COUNTIFS(Proyectos!$D$2:$D$41,$C29,Proyectos!$H$2:$H$41,"Bloqueado") | F29: =SUMIF(Proyectos!$D$2:$D$41,$C29,Proyectos!$N$2:$N$41) | G29: =SUMIF(Proyectos!$D$2:$D$41,$C29,Proyectos!$O$2:$O$41) | H29: =IFERROR(G29/F29,"") | I29: =IFERROR(AVERAGEIF(Proyectos!$D$2:$D$41,$C29,Proyectos!$L$2:$L$41),"") | J29: =SUMPRODUCT((Hitos!$J$2:$J$81=$C29)*(Hitos!$E$2:$E$81<>"")*(Hitos!$E$2:$E$81<TODAY())*(Hitos!$F$2:$F$81<>"Completado")*(Hitos!$F$2:$F$81<>"Cancelado")) | K29: =COUNTIFS(KPIs!$M$2:$M$71,$C29,KPIs!$O$2:$O$71,"Crítico") | BJ29: =IF(AND(Proyectos!$A29<>"",OR(Proyectos!$H29="En riesgo",Proyectos!$H29="Bloqueado",Proyectos!$AB29>0,IF(Proyectos!$V29="",FALSE,Proyectos!$V29<-0.15))),BK29,"") | BK29: =IF(AND(Proyectos!$A29<>"",OR(Proyectos!$H29="En riesgo",Proyectos!$H29="Bloqueado",Proyectos!$AB29>0,IF(Proyectos!$V29="",FALSE,Proyectos!$V29<-0.15))),N(BK28)+1,N(BK28)) | BN29: =IF(AND(Hitos!$A29<>"",OR(Hitos!$L29="Vencido",Hitos!$L29="Esta semana",Hitos!$L29="Próximos 30 días")),BO29,"") | BO29: =IF(AND(Hitos!$A29<>"",OR(Hitos!$L29="Vencido",Hitos!$L29="Esta semana",Hitos!$L29="Próximos 30 días")),N(BO28)+1,N(BO28))
B30: Growth | C30: Brand & Social | D30: =COUNTIF(Proyectos!$D$2:$D$41,$C30) | E30: =COUNTIFS(Proyectos!$D$2:$D$41,$C30,Proyectos!$H$2:$H$41,"En curso")+COUNTIFS(Proyectos!$D$2:$D$41,$C30,Proyectos!$H$2:$H$41,"En riesgo")+COUNTIFS(Proyectos!$D$2:$D$41,$C30,Proyectos!$H$2:$H$41,"Bloqueado") | F30: =SUMIF(Proyectos!$D$2:$D$41,$C30,Proyectos!$N$2:$N$41) | G30: =SUMIF(Proyectos!$D$2:$D$41,$C30,Proyectos!$O$2:$O$41) | H30: =IFERROR(G30/F30,"") | I30: =IFERROR(AVERAGEIF(Proyectos!$D$2:$D$41,$C30,Proyectos!$L$2:$L$41),"") | J30: =SUMPRODUCT((Hitos!$J$2:$J$81=$C30)*(Hitos!$E$2:$E$81<>"")*(Hitos!$E$2:$E$81<TODAY())*(Hitos!$F$2:$F$81<>"Completado")*(Hitos!$F$2:$F$81<>"Cancelado")) | K30: =COUNTIFS(KPIs!$M$2:$M$71,$C30,KPIs!$O$2:$O$71,"Crítico") | BJ30: =IF(AND(Proyectos!$A30<>"",OR(Proyectos!$H30="En riesgo",Proyectos!$H30="Bloqueado",Proyectos!$AB30>0,IF(Proyectos!$V30="",FALSE,Proyectos!$V30<-0.15))),BK30,"") | BK30: =IF(AND(Proyectos!$A30<>"",OR(Proyectos!$H30="En riesgo",Proyectos!$H30="Bloqueado",Proyectos!$AB30>0,IF(Proyectos!$V30="",FALSE,Proyectos!$V30<-0.15))),N(BK29)+1,N(BK29)) | BN30: =IF(AND(Hitos!$A30<>"",OR(Hitos!$L30="Vencido",Hitos!$L30="Esta semana",Hitos!$L30="Próximos 30 días")),BO30,"") | BO30: =IF(AND(Hitos!$A30<>"",OR(Hitos!$L30="Vencido",Hitos!$L30="Esta semana",Hitos!$L30="Próximos 30 días")),N(BO29)+1,N(BO29))
B31: Growth | C31: Data & Analytics | D31: =COUNTIF(Proyectos!$D$2:$D$41,$C31) | E31: =COUNTIFS(Proyectos!$D$2:$D$41,$C31,Proyectos!$H$2:$H$41,"En curso")+COUNTIFS(Proyectos!$D$2:$D$41,$C31,Proyectos!$H$2:$H$41,"En riesgo")+COUNTIFS(Proyectos!$D$2:$D$41,$C31,Proyectos!$H$2:$H$41,"Bloqueado") | F31: =SUMIF(Proyectos!$D$2:$D$41,$C31,Proyectos!$N$2:$N$41) | G31: =SUMIF(Proyectos!$D$2:$D$41,$C31,Proyectos!$O$2:$O$41) | H31: =IFERROR(G31/F31,"") | I31: =IFERROR(AVERAGEIF(Proyectos!$D$2:$D$41,$C31,Proyectos!$L$2:$L$41),"") | J31: =SUMPRODUCT((Hitos!$J$2:$J$81=$C31)*(Hitos!$E$2:$E$81<>"")*(Hitos!$E$2:$E$81<TODAY())*(Hitos!$F$2:$F$81<>"Completado")*(Hitos!$F$2:$F$81<>"Cancelado")) | K31: =COUNTIFS(KPIs!$M$2:$M$71,$C31,KPIs!$O$2:$O$71,"Crítico") | BJ31: =IF(AND(Proyectos!$A31<>"",OR(Proyectos!$H31="En riesgo",Proyectos!$H31="Bloqueado",Proyectos!$AB31>0,IF(Proyectos!$V31="",FALSE,Proyectos!$V31<-0.15))),BK31,"") | BK31: =IF(AND(Proyectos!$A31<>"",OR(Proyectos!$H31="En riesgo",Proyectos!$H31="Bloqueado",Proyectos!$AB31>0,IF(Proyectos!$V31="",FALSE,Proyectos!$V31<-0.15))),N(BK30)+1,N(BK30)) | BN31: =IF(AND(Hitos!$A31<>"",OR(Hitos!$L31="Vencido",Hitos!$L31="Esta semana",Hitos!$L31="Próximos 30 días")),BO31,"") | BO31: =IF(AND(Hitos!$A31<>"",OR(Hitos!$L31="Vencido",Hitos!$L31="Esta semana",Hitos!$L31="Próximos 30 días")),N(BO30)+1,N(BO30))
BJ32: =IF(AND(Proyectos!$A32<>"",OR(Proyectos!$H32="En riesgo",Proyectos!$H32="Bloqueado",Proyectos!$AB32>0,IF(Proyectos!$V32="",FALSE,Proyectos!$V32<-0.15))),BK32,"") | BK32: =IF(AND(Proyectos!$A32<>"",OR(Proyectos!$H32="En riesgo",Proyectos!$H32="Bloqueado",Proyectos!$AB32>0,IF(Proyectos!$V32="",FALSE,Proyectos!$V32<-0.15))),N(BK31)+1,N(BK31)) | BN32: =IF(AND(Hitos!$A32<>"",OR(Hitos!$L32="Vencido",Hitos!$L32="Esta semana",Hitos!$L32="Próximos 30 días")),BO32,"") | BO32: =IF(AND(Hitos!$A32<>"",OR(Hitos!$L32="Vencido",Hitos!$L32="Esta semana",Hitos!$L32="Próximos 30 días")),N(BO31)+1,N(BO31))
B33: PROYECTOS QUE REQUIEREN ATENCIÓN | F33: En riesgo · bloqueados · con hitos vencidos · desviados >15pp | BJ33: =IF(AND(Proyectos!$A33<>"",OR(Proyectos!$H33="En riesgo",Proyectos!$H33="Bloqueado",Proyectos!$AB33>0,IF(Proyectos!$V33="",FALSE,Proyectos!$V33<-0.15))),BK33,"") | BK33: =IF(AND(Proyectos!$A33<>"",OR(Proyectos!$H33="En riesgo",Proyectos!$H33="Bloqueado",Proyectos!$AB33>0,IF(Proyectos!$V33="",FALSE,Proyectos!$V33<-0.15))),N(BK32)+1,N(BK32)) | BN33: =IF(AND(Hitos!$A33<>"",OR(Hitos!$L33="Vencido",Hitos!$L33="Esta semana",Hitos!$L33="Próximos 30 días")),BO33,"") | BO33: =IF(AND(Hitos!$A33<>"",OR(Hitos!$L33="Vencido",Hitos!$L33="Esta semana",Hitos!$L33="Próximos 30 días")),N(BO32)+1,N(BO32))
B34: ID | C34: Proyecto | D34: Subárea | E34: Owner | F34: Prioridad | G34: Estado | H34: Fin previsto | I34: Avance | J34: Desviación | K34: Semáforo | L34: Hitos vencidos | M34: % KPIs | BJ34: =IF(AND(Proyectos!$A34<>"",OR(Proyectos!$H34="En riesgo",Proyectos!$H34="Bloqueado",Proyectos!$AB34>0,IF(Proyectos!$V34="",FALSE,Proyectos!$V34<-0.15))),BK34,"") | BK34: =IF(AND(Proyectos!$A34<>"",OR(Proyectos!$H34="En riesgo",Proyectos!$H34="Bloqueado",Proyectos!$AB34>0,IF(Proyectos!$V34="",FALSE,Proyectos!$V34<-0.15))),N(BK33)+1,N(BK33)) | BN34: =IF(AND(Hitos!$A34<>"",OR(Hitos!$L34="Vencido",Hitos!$L34="Esta semana",Hitos!$L34="Próximos 30 días")),BO34,"") | BO34: =IF(AND(Hitos!$A34<>"",OR(Hitos!$L34="Vencido",Hitos!$L34="Esta semana",Hitos!$L34="Próximos 30 días")),N(BO33)+1,N(BO33))
B35: =IF($BH35="","",INDEX(Proyectos!$A$2:$A$41,$BH35)) | C35: =IF($BH35="","",INDEX(Proyectos!$B$2:$B$41,$BH35)) | D35: =IF($BH35="","",INDEX(Proyectos!$D$2:$D$41,$BH35)) | E35: =IF($BH35="","",INDEX(Proyectos!$E$2:$E$41,$BH35)) | F35: =IF($BH35="","",INDEX(Proyectos!$G$2:$G$41,$BH35)) | G35: =IF($BH35="","",INDEX(Proyectos!$H$2:$H$41,$BH35)) | H35: =IF($BH35="","",INDEX(Proyectos!$K$2:$K$41,$BH35)) | I35: =IF($BH35="","",INDEX(Proyectos!$L$2:$L$41,$BH35)) | J35: =IF($BH35="","",INDEX(Proyectos!$V$2:$V$41,$BH35)) | K35: =IF($BH35="","",INDEX(Proyectos!$W$2:$W$41,$BH35)) | L35: =IF($BH35="","",INDEX(Proyectos!$AB$2:$AB$41,$BH35)) | M35: =IF($BH35="","",INDEX(Proyectos!$Y$2:$Y$41,$BH35)) | BH35: =IFERROR(MATCH(1,$BJ$2:$BJ$41,0),"") | BJ35: =IF(AND(Proyectos!$A35<>"",OR(Proyectos!$H35="En riesgo",Proyectos!$H35="Bloqueado",Proyectos!$AB35>0,IF(Proyectos!$V35="",FALSE,Proyectos!$V35<-0.15))),BK35,"") | BK35: =IF(AND(Proyectos!$A35<>"",OR(Proyectos!$H35="En riesgo",Proyectos!$H35="Bloqueado",Proyectos!$AB35>0,IF(Proyectos!$V35="",FALSE,Proyectos!$V35<-0.15))),N(BK34)+1,N(BK34)) | BN35: =IF(AND(Hitos!$A35<>"",OR(Hitos!$L35="Vencido",Hitos!$L35="Esta semana",Hitos!$L35="Próximos 30 días")),BO35,"") | BO35: =IF(AND(Hitos!$A35<>"",OR(Hitos!$L35="Vencido",Hitos!$L35="Esta semana",Hitos!$L35="Próximos 30 días")),N(BO34)+1,N(BO34))
B36: =IF($BH36="","",INDEX(Proyectos!$A$2:$A$41,$BH36)) | C36: =IF($BH36="","",INDEX(Proyectos!$B$2:$B$41,$BH36)) | D36: =IF($BH36="","",INDEX(Proyectos!$D$2:$D$41,$BH36)) | E36: =IF($BH36="","",INDEX(Proyectos!$E$2:$E$41,$BH36)) | F36: =IF($BH36="","",INDEX(Proyectos!$G$2:$G$41,$BH36)) | G36: =IF($BH36="","",INDEX(Proyectos!$H$2:$H$41,$BH36)) | H36: =IF($BH36="","",INDEX(Proyectos!$K$2:$K$41,$BH36)) | I36: =IF($BH36="","",INDEX(Proyectos!$L$2:$L$41,$BH36)) | J36: =IF($BH36="","",INDEX(Proyectos!$V$2:$V$41,$BH36)) | K36: =IF($BH36="","",INDEX(Proyectos!$W$2:$W$41,$BH36)) | L36: =IF($BH36="","",INDEX(Proyectos!$AB$2:$AB$41,$BH36)) | M36: =IF($BH36="","",INDEX(Proyectos!$Y$2:$Y$41,$BH36)) | BH36: =IFERROR(MATCH(2,$BJ$2:$BJ$41,0),"") | BJ36: =IF(AND(Proyectos!$A36<>"",OR(Proyectos!$H36="En riesgo",Proyectos!$H36="Bloqueado",Proyectos!$AB36>0,IF(Proyectos!$V36="",FALSE,Proyectos!$V36<-0.15))),BK36,"") | BK36: =IF(AND(Proyectos!$A36<>"",OR(Proyectos!$H36="En riesgo",Proyectos!$H36="Bloqueado",Proyectos!$AB36>0,IF(Proyectos!$V36="",FALSE,Proyectos!$V36<-0.15))),N(BK35)+1,N(BK35)) | BN36: =IF(AND(Hitos!$A36<>"",OR(Hitos!$L36="Vencido",Hitos!$L36="Esta semana",Hitos!$L36="Próximos 30 días")),BO36,"") | BO36: =IF(AND(Hitos!$A36<>"",OR(Hitos!$L36="Vencido",Hitos!$L36="Esta semana",Hitos!$L36="Próximos 30 días")),N(BO35)+1,N(BO35))
B37: =IF($BH37="","",INDEX(Proyectos!$A$2:$A$41,$BH37)) | C37: =IF($BH37="","",INDEX(Proyectos!$B$2:$B$41,$BH37)) | D37: =IF($BH37="","",INDEX(Proyectos!$D$2:$D$41,$BH37)) | E37: =IF($BH37="","",INDEX(Proyectos!$E$2:$E$41,$BH37)) | F37: =IF($BH37="","",INDEX(Proyectos!$G$2:$G$41,$BH37)) | G37: =IF($BH37="","",INDEX(Proyectos!$H$2:$H$41,$BH37)) | H37: =IF($BH37="","",INDEX(Proyectos!$K$2:$K$41,$BH37)) | I37: =IF($BH37="","",INDEX(Proyectos!$L$2:$L$41,$BH37)) | J37: =IF($BH37="","",INDEX(Proyectos!$V$2:$V$41,$BH37)) | K37: =IF($BH37="","",INDEX(Proyectos!$W$2:$W$41,$BH37)) | L37: =IF($BH37="","",INDEX(Proyectos!$AB$2:$AB$41,$BH37)) | M37: =IF($BH37="","",INDEX(Proyectos!$Y$2:$Y$41,$BH37)) | BH37: =IFERROR(MATCH(3,$BJ$2:$BJ$41,0),"") | BJ37: =IF(AND(Proyectos!$A37<>"",OR(Proyectos!$H37="En riesgo",Proyectos!$H37="Bloqueado",Proyectos!$AB37>0,IF(Proyectos!$V37="",FALSE,Proyectos!$V37<-0.15))),BK37,"") | BK37: =IF(AND(Proyectos!$A37<>"",OR(Proyectos!$H37="En riesgo",Proyectos!$H37="Bloqueado",Proyectos!$AB37>0,IF(Proyectos!$V37="",FALSE,Proyectos!$V37<-0.15))),N(BK36)+1,N(BK36)) | BN37: =IF(AND(Hitos!$A37<>"",OR(Hitos!$L37="Vencido",Hitos!$L37="Esta semana",Hitos!$L37="Próximos 30 días")),BO37,"") | BO37: =IF(AND(Hitos!$A37<>"",OR(Hitos!$L37="Vencido",Hitos!$L37="Esta semana",Hitos!$L37="Próximos 30 días")),N(BO36)+1,N(BO36))
B38: =IF($BH38="","",INDEX(Proyectos!$A$2:$A$41,$BH38)) | C38: =IF($BH38="","",INDEX(Proyectos!$B$2:$B$41,$BH38)) | D38: =IF($BH38="","",INDEX(Proyectos!$D$2:$D$41,$BH38)) | E38: =IF($BH38="","",INDEX(Proyectos!$E$2:$E$41,$BH38)) | F38: =IF($BH38="","",INDEX(Proyectos!$G$2:$G$41,$BH38)) | G38: =IF($BH38="","",INDEX(Proyectos!$H$2:$H$41,$BH38)) | H38: =IF($BH38="","",INDEX(Proyectos!$K$2:$K$41,$BH38)) | I38: =IF($BH38="","",INDEX(Proyectos!$L$2:$L$41,$BH38)) | J38: =IF($BH38="","",INDEX(Proyectos!$V$2:$V$41,$BH38)) | K38: =IF($BH38="","",INDEX(Proyectos!$W$2:$W$41,$BH38)) | L38: =IF($BH38="","",INDEX(Proyectos!$AB$2:$AB$41,$BH38)) | M38: =IF($BH38="","",INDEX(Proyectos!$Y$2:$Y$41,$BH38)) | BH38: =IFERROR(MATCH(4,$BJ$2:$BJ$41,0),"") | BJ38: =IF(AND(Proyectos!$A38<>"",OR(Proyectos!$H38="En riesgo",Proyectos!$H38="Bloqueado",Proyectos!$AB38>0,IF(Proyectos!$V38="",FALSE,Proyectos!$V38<-0.15))),BK38,"") | BK38: =IF(AND(Proyectos!$A38<>"",OR(Proyectos!$H38="En riesgo",Proyectos!$H38="Bloqueado",Proyectos!$AB38>0,IF(Proyectos!$V38="",FALSE,Proyectos!$V38<-0.15))),N(BK37)+1,N(BK37)) | BN38: =IF(AND(Hitos!$A38<>"",OR(Hitos!$L38="Vencido",Hitos!$L38="Esta semana",Hitos!$L38="Próximos 30 días")),BO38,"") | BO38: =IF(AND(Hitos!$A38<>"",OR(Hitos!$L38="Vencido",Hitos!$L38="Esta semana",Hitos!$L38="Próximos 30 días")),N(BO37)+1,N(BO37))
B39: =IF($BH39="","",INDEX(Proyectos!$A$2:$A$41,$BH39)) | C39: =IF($BH39="","",INDEX(Proyectos!$B$2:$B$41,$BH39)) | D39: =IF($BH39="","",INDEX(Proyectos!$D$2:$D$41,$BH39)) | E39: =IF($BH39="","",INDEX(Proyectos!$E$2:$E$41,$BH39)) | F39: =IF($BH39="","",INDEX(Proyectos!$G$2:$G$41,$BH39)) | G39: =IF($BH39="","",INDEX(Proyectos!$H$2:$H$41,$BH39)) | H39: =IF($BH39="","",INDEX(Proyectos!$K$2:$K$41,$BH39)) | I39: =IF($BH39="","",INDEX(Proyectos!$L$2:$L$41,$BH39)) | J39: =IF($BH39="","",INDEX(Proyectos!$V$2:$V$41,$BH39)) | K39: =IF($BH39="","",INDEX(Proyectos!$W$2:$W$41,$BH39)) | L39: =IF($BH39="","",INDEX(Proyectos!$AB$2:$AB$41,$BH39)) | M39: =IF($BH39="","",INDEX(Proyectos!$Y$2:$Y$41,$BH39)) | BH39: =IFERROR(MATCH(5,$BJ$2:$BJ$41,0),"") | BJ39: =IF(AND(Proyectos!$A39<>"",OR(Proyectos!$H39="En riesgo",Proyectos!$H39="Bloqueado",Proyectos!$AB39>0,IF(Proyectos!$V39="",FALSE,Proyectos!$V39<-0.15))),BK39,"") | BK39: =IF(AND(Proyectos!$A39<>"",OR(Proyectos!$H39="En riesgo",Proyectos!$H39="Bloqueado",Proyectos!$AB39>0,IF(Proyectos!$V39="",FALSE,Proyectos!$V39<-0.15))),N(BK38)+1,N(BK38)) | BN39: =IF(AND(Hitos!$A39<>"",OR(Hitos!$L39="Vencido",Hitos!$L39="Esta semana",Hitos!$L39="Próximos 30 días")),BO39,"") | BO39: =IF(AND(Hitos!$A39<>"",OR(Hitos!$L39="Vencido",Hitos!$L39="Esta semana",Hitos!$L39="Próximos 30 días")),N(BO38)+1,N(BO38))
B40: =IF($BH40="","",INDEX(Proyectos!$A$2:$A$41,$BH40)) | C40: =IF($BH40="","",INDEX(Proyectos!$B$2:$B$41,$BH40)) | D40: =IF($BH40="","",INDEX(Proyectos!$D$2:$D$41,$BH40)) | E40: =IF($BH40="","",INDEX(Proyectos!$E$2:$E$41,$BH40)) | F40: =IF($BH40="","",INDEX(Proyectos!$G$2:$G$41,$BH40)) | G40: =IF($BH40="","",INDEX(Proyectos!$H$2:$H$41,$BH40)) | H40: =IF($BH40="","",INDEX(Proyectos!$K$2:$K$41,$BH40)) | I40: =IF($BH40="","",INDEX(Proyectos!$L$2:$L$41,$BH40)) | J40: =IF($BH40="","",INDEX(Proyectos!$V$2:$V$41,$BH40)) | K40: =IF($BH40="","",INDEX(Proyectos!$W$2:$W$41,$BH40)) | L40: =IF($BH40="","",INDEX(Proyectos!$AB$2:$AB$41,$BH40)) | M40: =IF($BH40="","",INDEX(Proyectos!$Y$2:$Y$41,$BH40)) | BH40: =IFERROR(MATCH(6,$BJ$2:$BJ$41,0),"") | BJ40: =IF(AND(Proyectos!$A40<>"",OR(Proyectos!$H40="En riesgo",Proyectos!$H40="Bloqueado",Proyectos!$AB40>0,IF(Proyectos!$V40="",FALSE,Proyectos!$V40<-0.15))),BK40,"") | BK40: =IF(AND(Proyectos!$A40<>"",OR(Proyectos!$H40="En riesgo",Proyectos!$H40="Bloqueado",Proyectos!$AB40>0,IF(Proyectos!$V40="",FALSE,Proyectos!$V40<-0.15))),N(BK39)+1,N(BK39)) | BN40: =IF(AND(Hitos!$A40<>"",OR(Hitos!$L40="Vencido",Hitos!$L40="Esta semana",Hitos!$L40="Próximos 30 días")),BO40,"") | BO40: =IF(AND(Hitos!$A40<>"",OR(Hitos!$L40="Vencido",Hitos!$L40="Esta semana",Hitos!$L40="Próximos 30 días")),N(BO39)+1,N(BO39))
B41: =IF($BH41="","",INDEX(Proyectos!$A$2:$A$41,$BH41)) | C41: =IF($BH41="","",INDEX(Proyectos!$B$2:$B$41,$BH41)) | D41: =IF($BH41="","",INDEX(Proyectos!$D$2:$D$41,$BH41)) | E41: =IF($BH41="","",INDEX(Proyectos!$E$2:$E$41,$BH41)) | F41: =IF($BH41="","",INDEX(Proyectos!$G$2:$G$41,$BH41)) | G41: =IF($BH41="","",INDEX(Proyectos!$H$2:$H$41,$BH41)) | H41: =IF($BH41="","",INDEX(Proyectos!$K$2:$K$41,$BH41)) | I41: =IF($BH41="","",INDEX(Proyectos!$L$2:$L$41,$BH41)) | J41: =IF($BH41="","",INDEX(Proyectos!$V$2:$V$41,$BH41)) | K41: =IF($BH41="","",INDEX(Proyectos!$W$2:$W$41,$BH41)) | L41: =IF($BH41="","",INDEX(Proyectos!$AB$2:$AB$41,$BH41)) | M41: =IF($BH41="","",INDEX(Proyectos!$Y$2:$Y$41,$BH41)) | BH41: =IFERROR(MATCH(7,$BJ$2:$BJ$41,0),"") | BJ41: =IF(AND(Proyectos!$A41<>"",OR(Proyectos!$H41="En riesgo",Proyectos!$H41="Bloqueado",Proyectos!$AB41>0,IF(Proyectos!$V41="",FALSE,Proyectos!$V41<-0.15))),BK41,"") | BK41: =IF(AND(Proyectos!$A41<>"",OR(Proyectos!$H41="En riesgo",Proyectos!$H41="Bloqueado",Proyectos!$AB41>0,IF(Proyectos!$V41="",FALSE,Proyectos!$V41<-0.15))),N(BK40)+1,N(BK40)) | BN41: =IF(AND(Hitos!$A41<>"",OR(Hitos!$L41="Vencido",Hitos!$L41="Esta semana",Hitos!$L41="Próximos 30 días")),BO41,"") | BO41: =IF(AND(Hitos!$A41<>"",OR(Hitos!$L41="Vencido",Hitos!$L41="Esta semana",Hitos!$L41="Próximos 30 días")),N(BO40)+1,N(BO40))
...

Sheet Zoom departamento
B2: Zoom por departamento | BJ2: =IF(AND(Proyectos!$A2<>"",OR($C$5="(Todos)",Proyectos!$C2=$C$5),OR($C$6="(Todas)",Proyectos!$D2=$C$6),OR($C$7="(Todos)",Proyectos!$H2=$C$7)),BK2,"") | BK2: =IF(AND(Proyectos!$A2<>"",OR($C$5="(Todos)",Proyectos!$C2=$C$5),OR($C$6="(Todas)",Proyectos!$D2=$C$6),OR($C$7="(Todos)",Proyectos!$H2=$C$7)),N(BK1)+1,N(BK1)) | BN2: =IF(AND(KPIs!$A2<>"",OR($C$5="(Todos)",KPIs!$L2=$C$5),OR($C$6="(Todas)",KPIs!$M2=$C$6)),BO2,"") | BO2: =IF(AND(KPIs!$A2<>"",OR($C$5="(Todos)",KPIs!$L2=$C$5),OR($C$6="(Todas)",KPIs!$M2=$C$6)),N(BO1)+1,N(BO1)) | BR2: =IF(AND(Hitos!$A2<>"",OR($C$5="(Todos)",Hitos!$I2=$C$5),OR($C$6="(Todas)",Hitos!$J2=$C$6),OR(Hitos!$L2="Vencido",Hitos!$L2="Esta semana",Hitos!$L2="Próximos 30 días")),BS2,"") | BS2: =IF(AND(Hitos!$A2<>"",OR($C$5="(Todos)",Hitos!$I2=$C$5),OR($C$6="(Todas)",Hitos!$J2=$C$6),OR(Hitos!$L2="Vencido",Hitos!$L2="Esta semana",Hitos!$L2="Próximos 30 días")),N(BS1)+1,N(BS1))
B3: Elige departamento, subárea y estado en los desplegables: las tres tablas de abajo y las tarjetas se recalculan solas. | BJ3: =IF(AND(Proyectos!$A3<>"",OR($C$5="(Todos)",Proyectos!$C3=$C$5),OR($C$6="(Todas)",Proyectos!$D3=$C$6),OR($C$7="(Todos)",Proyectos!$H3=$C$7)),BK3,"") | BK3: =IF(AND(Proyectos!$A3<>"",OR($C$5="(Todos)",Proyectos!$C3=$C$5),OR($C$6="(Todas)",Proyectos!$D3=$C$6),OR($C$7="(Todos)",Proyectos!$H3=$C$7)),N(BK2)+1,N(BK2)) | BN3: =IF(AND(KPIs!$A3<>"",OR($C$5="(Todos)",KPIs!$L3=$C$5),OR($C$6="(Todas)",KPIs!$M3=$C$6)),BO3,"") | BO3: =IF(AND(KPIs!$A3<>"",OR($C$5="(Todos)",KPIs!$L3=$C$5),OR($C$6="(Todas)",KPIs!$M3=$C$6)),N(BO2)+1,N(BO2)) | BR3: =IF(AND(Hitos!$A3<>"",OR($C$5="(Todos)",Hitos!$I3=$C$5),OR($C$6="(Todas)",Hitos!$J3=$C$6),OR(Hitos!$L3="Vencido",Hitos!$L3="Esta semana",Hitos!$L3="Próximos 30 días")),BS3,"") | BS3: =IF(AND(Hitos!$A3<>"",OR($C$5="(Todos)",Hitos!$I3=$C$5),OR($C$6="(Todas)",Hitos!$J3=$C$6),OR(Hitos!$L3="Vencido",Hitos!$L3="Esta semana",Hitos!$L3="Próximos 30 días")),N(BS2)+1,N(BS2))
BJ4: =IF(AND(Proyectos!$A4<>"",OR($C$5="(Todos)",Proyectos!$C4=$C$5),OR($C$6="(Todas)",Proyectos!$D4=$C$6),OR($C$7="(Todos)",Proyectos!$H4=$C$7)),BK4,"") | BK4: =IF(AND(Proyectos!$A4<>"",OR($C$5="(Todos)",Proyectos!$C4=$C$5),OR($C$6="(Todas)",Proyectos!$D4=$C$6),OR($C$7="(Todos)",Proyectos!$H4=$C$7)),N(BK3)+1,N(BK3)) | BN4: =IF(AND(KPIs!$A4<>"",OR($C$5="(Todos)",KPIs!$L4=$C$5),OR($C$6="(Todas)",KPIs!$M4=$C$6)),BO4,"") | BO4: =IF(AND(KPIs!$A4<>"",OR($C$5="(Todos)",KPIs!$L4=$C$5),OR($C$6="(Todas)",KPIs!$M4=$C$6)),N(BO3)+1,N(BO3)) | BR4: =IF(AND(Hitos!$A4<>"",OR($C$5="(Todos)",Hitos!$I4=$C$5),OR($C$6="(Todas)",Hitos!$J4=$C$6),OR(Hitos!$L4="Vencido",Hitos!$L4="Esta semana",Hitos!$L4="Próximos 30 días")),BS4,"") | BS4: =IF(AND(Hitos!$A4<>"",OR($C$5="(Todos)",Hitos!$I4=$C$5),OR($C$6="(Todas)",Hitos!$J4=$C$6),OR(Hitos!$L4="Vencido",Hitos!$L4="Esta semana",Hitos!$L4="Próximos 30 días")),N(BS3)+1,N(BS3))
B5: Departamento | C5: (Todos) | G5: Celdas amarillas = filtros editables. El resto de la hoja es fórmula. | BJ5: =IF(AND(Proyectos!$A5<>"",OR($C$5="(Todos)",Proyectos!$C5=$C$5),OR($C$6="(Todas)",Proyectos!$D5=$C$6),OR($C$7="(Todos)",Proyectos!$H5=$C$7)),BK5,"") | BK5: =IF(AND(Proyectos!$A5<>"",OR($C$5="(Todos)",Proyectos!$C5=$C$5),OR($C$6="(Todas)",Proyectos!$D5=$C$6),OR($C$7="(Todos)",Proyectos!$H5=$C$7)),N(BK4)+1,N(BK4)) | BN5: =IF(AND(KPIs!$A5<>"",OR($C$5="(Todos)",KPIs!$L5=$C$5),OR($C$6="(Todas)",KPIs!$M5=$C$6)),BO5,"") | BO5: =IF(AND(KPIs!$A5<>"",OR($C$5="(Todos)",KPIs!$L5=$C$5),OR($C$6="(Todas)",KPIs!$M5=$C$6)),N(BO4)+1,N(BO4)) | BR5: =IF(AND(Hitos!$A5<>"",OR($C$5="(Todos)",Hitos!$I5=$C$5),OR($C$6="(Todas)",Hitos!$J5=$C$6),OR(Hitos!$L5="Vencido",Hitos!$L5="Esta semana",Hitos!$L5="Próximos 30 días")),BS5,"") | BS5: =IF(AND(Hitos!$A5<>"",OR($C$5="(Todos)",Hitos!$I5=$C$5),OR($C$6="(Todas)",Hitos!$J5=$C$6),OR(Hitos!$L5="Vencido",Hitos!$L5="Esta semana",Hitos!$L5="Próximos 30 días")),N(BS4)+1,N(BS4))
B6: Subárea | C6: (Todas) | BJ6: =IF(AND(Proyectos!$A6<>"",OR($C$5="(Todos)",Proyectos!$C6=$C$5),OR($C$6="(Todas)",Proyectos!$D6=$C$6),OR($C$7="(Todos)",Proyectos!$H6=$C$7)),BK6,"") | BK6: =IF(AND(Proyectos!$A6<>"",OR($C$5="(Todos)",Proyectos!$C6=$C$5),OR($C$6="(Todas)",Proyectos!$D6=$C$6),OR($C$7="(Todos)",Proyectos!$H6=$C$7)),N(BK5)+1,N(BK5)) | BN6: =IF(AND(KPIs!$A6<>"",OR($C$5="(Todos)",KPIs!$L6=$C$5),OR($C$6="(Todas)",KPIs!$M6=$C$6)),BO6,"") | BO6: =IF(AND(KPIs!$A6<>"",OR($C$5="(Todos)",KPIs!$L6=$C$5),OR($C$6="(Todas)",KPIs!$M6=$C$6)),N(BO5)+1,N(BO5)) | BR6: =IF(AND(Hitos!$A6<>"",OR($C$5="(Todos)",Hitos!$I6=$C$5),OR($C$6="(Todas)",Hitos!$J6=$C$6),OR(Hitos!$L6="Vencido",Hitos!$L6="Esta semana",Hitos!$L6="Próximos 30 días")),BS6,"") | BS6: =IF(AND(Hitos!$A6<>"",OR($C$5="(Todos)",Hitos!$I6=$C$5),OR($C$6="(Todas)",Hitos!$J6=$C$6),OR(Hitos!$L6="Vencido",Hitos!$L6="Esta semana",Hitos!$L6="Próximos 30 días")),N(BS5)+1,N(BS5))
B7: Estado | C7: (Todos) | BJ7: =IF(AND(Proyectos!$A7<>"",OR($C$5="(Todos)",Proyectos!$C7=$C$5),OR($C$6="(Todas)",Proyectos!$D7=$C$6),OR($C$7="(Todos)",Proyectos!$H7=$C$7)),BK7,"") | BK7: =IF(AND(Proyectos!$A7<>"",OR($C$5="(Todos)",Proyectos!$C7=$C$5),OR($C$6="(Todas)",Proyectos!$D7=$C$6),OR($C$7="(Todos)",Proyectos!$H7=$C$7)),N(BK6)+1,N(BK6)) | BN7: =IF(AND(KPIs!$A7<>"",OR($C$5="(Todos)",KPIs!$L7=$C$5),OR($C$6="(Todas)",KPIs!$M7=$C$6)),BO7,"") | BO7: =IF(AND(KPIs!$A7<>"",OR($C$5="(Todos)",KPIs!$L7=$C$5),OR($C$6="(Todas)",KPIs!$M7=$C$6)),N(BO6)+1,N(BO6)) | BR7: =IF(AND(Hitos!$A7<>"",OR($C$5="(Todos)",Hitos!$I7=$C$5),OR($C$6="(Todas)",Hitos!$J7=$C$6),OR(Hitos!$L7="Vencido",Hitos!$L7="Esta semana",Hitos!$L7="Próximos 30 días")),BS7,"") | BS7: =IF(AND(Hitos!$A7<>"",OR($C$5="(Todos)",Hitos!$I7=$C$5),OR($C$6="(Todas)",Hitos!$J7=$C$6),OR(Hitos!$L7="Vencido",Hitos!$L7="Esta semana",Hitos!$L7="Próximos 30 días")),N(BS6)+1,N(BS6))
BJ8: =IF(AND(Proyectos!$A8<>"",OR($C$5="(Todos)",Proyectos!$C8=$C$5),OR($C$6="(Todas)",Proyectos!$D8=$C$6),OR($C$7="(Todos)",Proyectos!$H8=$C$7)),BK8,"") | BK8: =IF(AND(Proyectos!$A8<>"",OR($C$5="(Todos)",Proyectos!$C8=$C$5),OR($C$6="(Todas)",Proyectos!$D8=$C$6),OR($C$7="(Todos)",Proyectos!$H8=$C$7)),N(BK7)+1,N(BK7)) | BN8: =IF(AND(KPIs!$A8<>"",OR($C$5="(Todos)",KPIs!$L8=$C$5),OR($C$6="(Todas)",KPIs!$M8=$C$6)),BO8,"") | BO8: =IF(AND(KPIs!$A8<>"",OR($C$5="(Todos)",KPIs!$L8=$C$5),OR($C$6="(Todas)",KPIs!$M8=$C$6)),N(BO7)+1,N(BO7)) | BR8: =IF(AND(Hitos!$A8<>"",OR($C$5="(Todos)",Hitos!$I8=$C$5),OR($C$6="(Todas)",Hitos!$J8=$C$6),OR(Hitos!$L8="Vencido",Hitos!$L8="Esta semana",Hitos!$L8="Próximos 30 días")),BS8,"") | BS8: =IF(AND(Hitos!$A8<>"",OR($C$5="(Todos)",Hitos!$I8=$C$5),OR($C$6="(Todas)",Hitos!$J8=$C$6),OR(Hitos!$L8="Vencido",Hitos!$L8="Esta semana",Hitos!$L8="Próximos 30 días")),N(BS7)+1,N(BS7))
B9: Proyectos en el filtro | C9: Activos | D9: En riesgo o bloqueados | E9: Avance medio | F9: Presupuesto | G9: Gasto | H9: % consumido | I9: Hitos vencidos | J9: KPIs en crítico | BJ9: =IF(AND(Proyectos!$A9<>"",OR($C$5="(Todos)",Proyectos!$C9=$C$5),OR($C$6="(Todas)",Proyectos!$D9=$C$6),OR($C$7="(Todos)",Proyectos!$H9=$C$7)),BK9,"") | BK9: =IF(AND(Proyectos!$A9<>"",OR($C$5="(Todos)",Proyectos!$C9=$C$5),OR($C$6="(Todas)",Proyectos!$D9=$C$6),OR($C$7="(Todos)",Proyectos!$H9=$C$7)),N(BK8)+1,N(BK8)) | BN9: =IF(AND(KPIs!$A9<>"",OR($C$5="(Todos)",KPIs!$L9=$C$5),OR($C$6="(Todas)",KPIs!$M9=$C$6)),BO9,"") | BO9: =IF(AND(KPIs!$A9<>"",OR($C$5="(Todos)",KPIs!$L9=$C$5),OR($C$6="(Todas)",KPIs!$M9=$C$6)),N(BO8)+1,N(BO8)) | BR9: =IF(AND(Hitos!$A9<>"",OR($C$5="(Todos)",Hitos!$I9=$C$5),OR($C$6="(Todas)",Hitos!$J9=$C$6),OR(Hitos!$L9="Vencido",Hitos!$L9="Esta semana",Hitos!$L9="Próximos 30 días")),BS9,"") | BS9: =IF(AND(Hitos!$A9<>"",OR($C$5="(Todos)",Hitos!$I9=$C$5),OR($C$6="(Todas)",Hitos!$J9=$C$6),OR(Hitos!$L9="Vencido",Hitos!$L9="Esta semana",Hitos!$L9="Próximos 30 días")),N(BS8)+1,N(BS8))
B10: =SUMPRODUCT((Proyectos!$A$2:$A$41<>"")*(($C$5="(Todos)")+(Proyectos!$C$2:$C$41=$C$5)>0)*(($C$6="(Todas)")+(Proyectos!$D$2:$D$41=$C$6)>0)*(($C$7="(Todos)")+(Proyectos!$H$2:$H$41=$C$7)>0)) | C10: =SUMPRODUCT((Proyectos!$A$2:$A$41<>"")*(($C$5="(Todos)")+(Proyectos!$C$2:$C$41=$C$5)>0)*(($C$6="(Todas)")+(Proyectos!$D$2:$D$41=$C$6)>0)*(($C$7="(Todos)")+(Proyectos!$H$2:$H$41=$C$7)>0)*(((Proyectos!$H$2:$H$41="En curso")+(Proyectos!$H$2:$H$41="En riesgo")+(Proyectos!$H$2:$H$41="Bloqueado"))>0)) | D10: =SUMPRODUCT((Proyectos!$A$2:$A$41<>"")*(($C$5="(Todos)")+(Proyectos!$C$2:$C$41=$C$5)>0)*(($C$6="(Todas)")+(Proyectos!$D$2:$D$41=$C$6)>0)*(($C$7="(Todos)")+(Proyectos!$H$2:$H$41=$C$7)>0)*(((Proyectos!$H$2:$H$41="En riesgo")+(Proyectos!$H$2:$H$41="Bloqueado"))>0)) | E10: =IFERROR(SUMPRODUCT((Proyectos!$A$2:$A$41<>"")*(($C$5="(Todos)")+(Proyectos!$C$2:$C$41=$C$5)>0)*(($C$6="(Todas)")+(Proyectos!$D$2:$D$41=$C$6)>0)*(($C$7="(Todos)")+(Proyectos!$H$2:$H$41=$C$7)>0)*Proyectos!$L$2:$L$41)/SUMPRODUCT((Proyectos!$A$2:$A$41<>"")*(($C$5="(Todos)")+(Proyectos!$C$2:$C$41=$C$5)>0)*(($C$6="(Todas)")+(Proyectos!$D$2:$D$41=$C$6)>0)*(($C$7="(Todos)")+(Proyectos!$H$2:$H$41=$C$7)>0)),"") | F10: =SUMPRODUCT((Proyectos!$A$2:$A$41<>"")*(($C$5="(Todos)")+(Proyectos!$C$2:$C$41=$C$5)>0)*(($C$6="(Todas)")+(Proyectos!$D$2:$D$41=$C$6)>0)*(($C$7="(Todos)")+(Proyectos!$H$2:$H$41=$C$7)>0)*Proyectos!$N$2:$N$41) | G10: =SUMPRODUCT((Proyectos!$A$2:$A$41<>"")*(($C$5="(Todos)")+(Proyectos!$C$2:$C$41=$C$5)>0)*(($C$6="(Todas)")+(Proyectos!$D$2:$D$41=$C$6)>0)*(($C$7="(Todos)")+(Proyectos!$H$2:$H$41=$C$7)>0)*Proyectos!$O$2:$O$41) | H10: =IFERROR(SUMPRODUCT((Proyectos!$A$2:$A$41<>"")*(($C$5="(Todos)")+(Proyectos!$C$2:$C$41=$C$5)>0)*(($C$6="(Todas)")+(Proyectos!$D$2:$D$41=$C$6)>0)*(($C$7="(Todos)")+(Proyectos!$H$2:$H$41=$C$7)>0)*Proyectos!$O$2:$O$41)/SUMPRODUCT((Proyectos!$A$2:$A$41<>"")*(($C$5="(Todos)")+(Proyectos!$C$2:$C$41=$C$5)>0)*(($C$6="(Todas)")+(Proyectos!$D$2:$D$41=$C$6)>0)*(($C$7="(Todos)")+(Proyectos!$H$2:$H$41=$C$7)>0)*Proyectos!$N$2:$N$41),"") | I10: =SUMPRODUCT((Hitos!$A$2:$A$81<>"")*(($C$5="(Todos)")+(Hitos!$I$2:$I$81=$C$5)>0)*(($C$6="(Todas)")+(Hitos!$J$2:$J$81=$C$6)>0)*(Hitos!$E$2:$E$81<>"")*(Hitos!$E$2:$E$81<TODAY())*(Hitos!$F$2:$F$81<>"Completado")*(Hitos!$F$2:$F$81<>"Cancelado")) | J10: =SUMPRODUCT((KPIs!$A$2:$A$71<>"")*(($C$5="(Todos)")+(KPIs!$L$2:$L$71=$C$5)>0)*(($C$6="(Todas)")+(KPIs!$M$2:$M$71=$C$6)>0)*(KPIs!$O$2:$O$71="Crítico")) | BJ10: =IF(AND(Proyectos!$A10<>"",OR($C$5="(Todos)",Proyectos!$C10=$C$5),OR($C$6="(Todas)",Proyectos!$D10=$C$6),OR($C$7="(Todos)",Proyectos!$H10=$C$7)),BK10,"") | BK10: =IF(AND(Proyectos!$A10<>"",OR($C$5="(Todos)",Proyectos!$C10=$C$5),OR($C$6="(Todas)",Proyectos!$D10=$C$6),OR($C$7="(Todos)",Proyectos!$H10=$C$7)),N(BK9)+1,N(BK9)) | BN10: =IF(AND(KPIs!$A10<>"",OR($C$5="(Todos)",KPIs!$L10=$C$5),OR($C$6="(Todas)",KPIs!$M10=$C$6)),BO10,"") | BO10: =IF(AND(KPIs!$A10<>"",OR($C$5="(Todos)",KPIs!$L10=$C$5),OR($C$6="(Todas)",KPIs!$M10=$C$6)),N(BO9)+1,N(BO9)) | BR10: =IF(AND(Hitos!$A10<>"",OR($C$5="(Todos)",Hitos!$I10=$C$5),OR($C$6="(Todas)",Hitos!$J10=$C$6),OR(Hitos!$L10="Vencido",Hitos!$L10="Esta semana",Hitos!$L10="Próximos 30 días")),BS10,"") | BS10: =IF(AND(Hitos!$A10<>"",OR($C$5="(Todos)",Hitos!$I10=$C$5),OR($C$6="(Todas)",Hitos!$J10=$C$6),OR(Hitos!$L10="Vencido",Hitos!$L10="Esta semana",Hitos!$L10="Próximos 30 días")),N(BS9)+1,N(BS9))
BJ11: =IF(AND(Proyectos!$A11<>"",OR($C$5="(Todos)",Proyectos!$C11=$C$5),OR($C$6="(Todas)",Proyectos!$D11=$C$6),OR($C$7="(Todos)",Proyectos!$H11=$C$7)),BK11,"") | BK11: =IF(AND(Proyectos!$A11<>"",OR($C$5="(Todos)",Proyectos!$C11=$C$5),OR($C$6="(Todas)",Proyectos!$D11=$C$6),OR($C$7="(Todos)",Proyectos!$H11=$C$7)),N(BK10)+1,N(BK10)) | BN11: =IF(AND(KPIs!$A11<>"",OR($C$5="(Todos)",KPIs!$L11=$C$5),OR($C$6="(Todas)",KPIs!$M11=$C$6)),BO11,"") | BO11: =IF(AND(KPIs!$A11<>"",OR($C$5="(Todos)",KPIs!$L11=$C$5),OR($C$6="(Todas)",KPIs!$M11=$C$6)),N(BO10)+1,N(BO10)) | BR11: =IF(AND(Hitos!$A11<>"",OR($C$5="(Todos)",Hitos!$I11=$C$5),OR($C$6="(Todas)",Hitos!$J11=$C$6),OR(Hitos!$L11="Vencido",Hitos!$L11="Esta semana",Hitos!$L11="Próximos 30 días")),BS11,"") | BS11: =IF(AND(Hitos!$A11<>"",OR($C$5="(Todos)",Hitos!$I11=$C$5),OR($C$6="(Todas)",Hitos!$J11=$C$6),OR(Hitos!$L11="Vencido",Hitos!$L11="Esta semana",Hitos!$L11="Próximos 30 días")),N(BS10)+1,N(BS10))
B12: PROYECTOS DEL FILTRO | BJ12: =IF(AND(Proyectos!$A12<>"",OR($C$5="(Todos)",Proyectos!$C12=$C$5),OR($C$6="(Todas)",Proyectos!$D12=$C$6),OR($C$7="(Todos)",Proyectos!$H12=$C$7)),BK12,"") | BK12: =IF(AND(Proyectos!$A12<>"",OR($C$5="(Todos)",Proyectos!$C12=$C$5),OR($C$6="(Todas)",Proyectos!$D12=$C$6),OR($C$7="(Todos)",Proyectos!$H12=$C$7)),N(BK11)+1,N(BK11)) | BN12: =IF(AND(KPIs!$A12<>"",OR($C$5="(Todos)",KPIs!$L12=$C$5),OR($C$6="(Todas)",KPIs!$M12=$C$6)),BO12,"") | BO12: =IF(AND(KPIs!$A12<>"",OR($C$5="(Todos)",KPIs!$L12=$C$5),OR($C$6="(Todas)",KPIs!$M12=$C$6)),N(BO11)+1,N(BO11)) | BR12: =IF(AND(Hitos!$A12<>"",OR($C$5="(Todos)",Hitos!$I12=$C$5),OR($C$6="(Todas)",Hitos!$J12=$C$6),OR(Hitos!$L12="Vencido",Hitos!$L12="Esta semana",Hitos!$L12="Próximos 30 días")),BS12,"") | BS12: =IF(AND(Hitos!$A12<>"",OR($C$5="(Todos)",Hitos!$I12=$C$5),OR($C$6="(Todas)",Hitos!$J12=$C$6),OR(Hitos!$L12="Vencido",Hitos!$L12="Esta semana",Hitos!$L12="Próximos 30 días")),N(BS11)+1,N(BS11))
B13: ID | C13: Proyecto | D13: Subárea | E13: Owner | F13: Prioridad | G13: Estado | H13: Fase | I13: Fin previsto | J13: Avance | K13: Esperado | L13: Desviación | M13: Semáforo | N13: Presupuesto € | O13: Gasto € | P13: % ppto | Q13: % KPIs | R13: Hitos vencidos | BJ13: =IF(AND(Proyectos!$A13<>"",OR($C$5="(Todos)",Proyectos!$C13=$C$5),OR($C$6="(Todas)",Proyectos!$D13=$C$6),OR($C$7="(Todos)",Proyectos!$H13=$C$7)),BK13,"") | BK13: =IF(AND(Proyectos!$A13<>"",OR($C$5="(Todos)",Proyectos!$C13=$C$5),OR($C$6="(Todas)",Proyectos!$D13=$C$6),OR($C$7="(Todos)",Proyectos!$H13=$C$7)),N(BK12)+1,N(BK12)) | BN13: =IF(AND(KPIs!$A13<>"",OR($C$5="(Todos)",KPIs!$L13=$C$5),OR($C$6="(Todas)",KPIs!$M13=$C$6)),BO13,"") | BO13: =IF(AND(KPIs!$A13<>"",OR($C$5="(Todos)",KPIs!$L13=$C$5),OR($C$6="(Todas)",KPIs!$M13=$C$6)),N(BO12)+1,N(BO12)) | BR13: =IF(AND(Hitos!$A13<>"",OR($C$5="(Todos)",Hitos!$I13=$C$5),OR($C$6="(Todas)",Hitos!$J13=$C$6),OR(Hitos!$L13="Vencido",Hitos!$L13="Esta semana",Hitos!$L13="Próximos 30 días")),BS13,"") | BS13: =IF(AND(Hitos!$A13<>"",OR($C$5="(Todos)",Hitos!$I13=$C$5),OR($C$6="(Todas)",Hitos!$J13=$C$6),OR(Hitos!$L13="Vencido",Hitos!$L13="Esta semana",Hitos!$L13="Próximos 30 días")),N(BS12)+1,N(BS12))
B14: =IF($BH14="","",INDEX(Proyectos!$A$2:$A$41,$BH14)) | C14: =IF($BH14="","",INDEX(Proyectos!$B$2:$B$41,$BH14)) | D14: =IF($BH14="","",INDEX(Proyectos!$D$2:$D$41,$BH14)) | E14: =IF($BH14="","",INDEX(Proyectos!$E$2:$E$41,$BH14)) | F14: =IF($BH14="","",INDEX(Proyectos!$G$2:$G$41,$BH14)) | G14: =IF($BH14="","",INDEX(Proyectos!$H$2:$H$41,$BH14)) | H14: =IF($BH14="","",INDEX(Proyectos!$I$2:$I$41,$BH14)) | I14: =IF($BH14="","",INDEX(Proyectos!$K$2:$K$41,$BH14)) | J14: =IF($BH14="","",INDEX(Proyectos!$L$2:$L$41,$BH14)) | K14: =IF($BH14="","",INDEX(Proyectos!$U$2:$U$41,$BH14)) | L14: =IF($BH14="","",INDEX(Proyectos!$V$2:$V$41,$BH14)) | M14: =IF($BH14="","",INDEX(Proyectos!$W$2:$W$41,$BH14)) | N14: =IF($BH14="","",INDEX(Proyectos!$N$2:$N$41,$BH14)) | O14: =IF($BH14="","",INDEX(Proyectos!$O$2:$O$41,$BH14)) | P14: =IF($BH14="","",INDEX(Proyectos!$S$2:$S$41,$BH14)) | Q14: =IF($BH14="","",INDEX(Proyectos!$Y$2:$Y$41,$BH14)) | R14: =IF($BH14="","",INDEX(Proyectos!$AB$2:$AB$41,$BH14)) | BH14: =IFERROR(MATCH(1,$BJ$2:$BJ$41,0),"") | BJ14: =IF(AND(Proyectos!$A14<>"",OR($C$5="(Todos)",Proyectos!$C14=$C$5),OR($C$6="(Todas)",Proyectos!$D14=$C$6),OR($C$7="(Todos)",Proyectos!$H14=$C$7)),BK14,"") | BK14: =IF(AND(Proyectos!$A14<>"",OR($C$5="(Todos)",Proyectos!$C14=$C$5),OR($C$6="(Todas)",Proyectos!$D14=$C$6),OR($C$7="(Todos)",Proyectos!$H14=$C$7)),N(BK13)+1,N(BK13)) | BN14: =IF(AND(KPIs!$A14<>"",OR($C$5="(Todos)",KPIs!$L14=$C$5),OR($C$6="(Todas)",KPIs!$M14=$C$6)),BO14,"") | BO14: =IF(AND(KPIs!$A14<>"",OR($C$5="(Todos)",KPIs!$L14=$C$5),OR($C$6="(Todas)",KPIs!$M14=$C$6)),N(BO13)+1,N(BO13)) | BR14: =IF(AND(Hitos!$A14<>"",OR($C$5="(Todos)",Hitos!$I14=$C$5),OR($C$6="(Todas)",Hitos!$J14=$C$6),OR(Hitos!$L14="Vencido",Hitos!$L14="Esta semana",Hitos!$L14="Próximos 30 días")),BS14,"") | BS14: =IF(AND(Hitos!$A14<>"",OR($C$5="(Todos)",Hitos!$I14=$C$5),OR($C$6="(Todas)",Hitos!$J14=$C$6),OR(Hitos!$L14="Vencido",Hitos!$L14="Esta semana",Hitos!$L14="Próximos 30 días")),N(BS13)+1,N(BS13))
B15: =IF($BH15="","",INDEX(Proyectos!$A$2:$A$41,$BH15)) | C15: =IF($BH15="","",INDEX(Proyectos!$B$2:$B$41,$BH15)) | D15: =IF($BH15="","",INDEX(Proyectos!$D$2:$D$41,$BH15)) | E15: =IF($BH15="","",INDEX(Proyectos!$E$2:$E$41,$BH15)) | F15: =IF($BH15="","",INDEX(Proyectos!$G$2:$G$41,$BH15)) | G15: =IF($BH15="","",INDEX(Proyectos!$H$2:$H$41,$BH15)) | H15: =IF($BH15="","",INDEX(Proyectos!$I$2:$I$41,$BH15)) | I15: =IF($BH15="","",INDEX(Proyectos!$K$2:$K$41,$BH15)) | J15: =IF($BH15="","",INDEX(Proyectos!$L$2:$L$41,$BH15)) | K15: =IF($BH15="","",INDEX(Proyectos!$U$2:$U$41,$BH15)) | L15: =IF($BH15="","",INDEX(Proyectos!$V$2:$V$41,$BH15)) | M15: =IF($BH15="","",INDEX(Proyectos!$W$2:$W$41,$BH15)) | N15: =IF($BH15="","",INDEX(Proyectos!$N$2:$N$41,$BH15)) | O15: =IF($BH15="","",INDEX(Proyectos!$O$2:$O$41,$BH15)) | P15: =IF($BH15="","",INDEX(Proyectos!$S$2:$S$41,$BH15)) | Q15: =IF($BH15="","",INDEX(Proyectos!$Y$2:$Y$41,$BH15)) | R15: =IF($BH15="","",INDEX(Proyectos!$AB$2:$AB$41,$BH15)) | BH15: =IFERROR(MATCH(2,$BJ$2:$BJ$41,0),"") | BJ15: =IF(AND(Proyectos!$A15<>"",OR($C$5="(Todos)",Proyectos!$C15=$C$5),OR($C$6="(Todas)",Proyectos!$D15=$C$6),OR($C$7="(Todos)",Proyectos!$H15=$C$7)),BK15,"") | BK15: =IF(AND(Proyectos!$A15<>"",OR($C$5="(Todos)",Proyectos!$C15=$C$5),OR($C$6="(Todas)",Proyectos!$D15=$C$6),OR($C$7="(Todos)",Proyectos!$H15=$C$7)),N(BK14)+1,N(BK14)) | BN15: =IF(AND(KPIs!$A15<>"",OR($C$5="(Todos)",KPIs!$L15=$C$5),OR($C$6="(Todas)",KPIs!$M15=$C$6)),BO15,"") | BO15: =IF(AND(KPIs!$A15<>"",OR($C$5="(Todos)",KPIs!$L15=$C$5),OR($C$6="(Todas)",KPIs!$M15=$C$6)),N(BO14)+1,N(BO14)) | BR15: =IF(AND(Hitos!$A15<>"",OR($C$5="(Todos)",Hitos!$I15=$C$5),OR($C$6="(Todas)",Hitos!$J15=$C$6),OR(Hitos!$L15="Vencido",Hitos!$L15="Esta semana",Hitos!$L15="Próximos 30 días")),BS15,"") | BS15: =IF(AND(Hitos!$A15<>"",OR($C$5="(Todos)",Hitos!$I15=$C$5),OR($C$6="(Todas)",Hitos!$J15=$C$6),OR(Hitos!$L15="Vencido",Hitos!$L15="Esta semana",Hitos!$L15="Próximos 30 días")),N(BS14)+1,N(BS14))
